INFO 2025-10-07 05:12:16,276 autoreload 90746 140704670657024 Watching for file changes with StatReloader
INFO 2025-10-07 05:13:50,715 basehttp 90746 123145489719296 "OPTIONS /api/v1/public/all-extracted-content?page=1&page_size=10 HTTP/1.1" 200 0
INFO 2025-10-07 05:13:50,739 basehttp 90746 123145489719296 "OPTIONS /api/v1/public/all-extracted-content/?page=1&page_size=10 HTTP/1.1" 200 0
INFO 2025-10-07 05:13:58,890 basehttp 90746 123145506508800 "OPTIONS /api/v1/public/all-extracted-content?page=1&page_size=10 HTTP/1.1" 200 0
INFO 2025-10-07 05:13:58,954 basehttp 90746 123145506508800 "GET /api/v1/public/all-extracted-content?page=1&page_size=10 HTTP/1.1" 301 0
INFO 2025-10-07 05:13:58,966 basehttp 90746 123145506508800 "OPTIONS /api/v1/public/all-extracted-content/?page=1&page_size=10 HTTP/1.1" 200 0
ERROR 2025-10-07 05:14:57,277 log 90746 123145573666816 Internal Server Error: /api/v1/processing/rag/generate/
Traceback (most recent call last):
  File "/Users/krohn/PycharmProjects/DME-AGENTS/dgi-extractor/.venv/lib/python3.12/site-packages/django/db/backends/base/base.py", line 279, in ensure_connection
    self.connect()
  File "/Users/krohn/PycharmProjects/DME-AGENTS/dgi-extractor/.venv/lib/python3.12/site-packages/django/utils/asyncio.py", line 26, in inner
    return func(*args, **kwargs)
           ^^^^^^^^^^^^^^^^^^^^^
  File "/Users/krohn/PycharmProjects/DME-AGENTS/dgi-extractor/.venv/lib/python3.12/site-packages/django/db/backends/base/base.py", line 256, in connect
    self.connection = self.get_new_connection(conn_params)
                      ^^^^^^^^^^^^^^^^^^^^^^^^^^^^^^^^^^^^
  File "/Users/krohn/PycharmProjects/DME-AGENTS/dgi-extractor/.venv/lib/python3.12/site-packages/django/utils/asyncio.py", line 26, in inner
    return func(*args, **kwargs)
           ^^^^^^^^^^^^^^^^^^^^^
  File "/Users/krohn/PycharmProjects/DME-AGENTS/dgi-extractor/.venv/lib/python3.12/site-packages/django/db/backends/postgresql/base.py", line 332, in get_new_connection
    connection = self.Database.connect(**conn_params)
                 ^^^^^^^^^^^^^^^^^^^^^^^^^^^^^^^^^^^^
  File "/Users/krohn/PycharmProjects/DME-AGENTS/dgi-extractor/.venv/lib/python3.12/site-packages/psycopg2/__init__.py", line 122, in connect
    conn = _connect(dsn, connection_factory=connection_factory, **kwasync)
           ^^^^^^^^^^^^^^^^^^^^^^^^^^^^^^^^^^^^^^^^^^^^^^^^^^^^^^^^^^^^^^^
psycopg2.OperationalError: connection to server at "37.60.239.221", port 5433 failed: No route to host
	Is the server running on that host and accepting TCP/IP connections?


The above exception was the direct cause of the following exception:

Traceback (most recent call last):
  File "/Users/krohn/PycharmProjects/DME-AGENTS/dgi-extractor/.venv/lib/python3.12/site-packages/django/core/handlers/exception.py", line 55, in inner
    response = get_response(request)
               ^^^^^^^^^^^^^^^^^^^^^
  File "/Users/krohn/PycharmProjects/DME-AGENTS/dgi-extractor/.venv/lib/python3.12/site-packages/django/core/handlers/base.py", line 197, in _get_response
    response = wrapped_callback(request, *callback_args, **callback_kwargs)
               ^^^^^^^^^^^^^^^^^^^^^^^^^^^^^^^^^^^^^^^^^^^^^^^^^^^^^^^^^^^^
  File "/Library/Frameworks/Python.framework/Versions/3.12/lib/python3.12/contextlib.py", line 80, in inner
    with self._recreate_cm():
         ^^^^^^^^^^^^^^^^^^^
  File "/Users/krohn/PycharmProjects/DME-AGENTS/dgi-extractor/.venv/lib/python3.12/site-packages/django/db/transaction.py", line 198, in __enter__
    if not connection.get_autocommit():
           ^^^^^^^^^^^^^^^^^^^^^^^^^^^
  File "/Users/krohn/PycharmProjects/DME-AGENTS/dgi-extractor/.venv/lib/python3.12/site-packages/django/db/backends/base/base.py", line 454, in get_autocommit
    self.ensure_connection()
  File "/Users/krohn/PycharmProjects/DME-AGENTS/dgi-extractor/.venv/lib/python3.12/site-packages/django/utils/asyncio.py", line 26, in inner
    return func(*args, **kwargs)
           ^^^^^^^^^^^^^^^^^^^^^
  File "/Users/krohn/PycharmProjects/DME-AGENTS/dgi-extractor/.venv/lib/python3.12/site-packages/django/db/backends/base/base.py", line 278, in ensure_connection
    with self.wrap_database_errors:
         ^^^^^^^^^^^^^^^^^^^^^^^^^
  File "/Users/krohn/PycharmProjects/DME-AGENTS/dgi-extractor/.venv/lib/python3.12/site-packages/django/db/utils.py", line 91, in __exit__
    raise dj_exc_value.with_traceback(traceback) from exc_value
  File "/Users/krohn/PycharmProjects/DME-AGENTS/dgi-extractor/.venv/lib/python3.12/site-packages/django/db/backends/base/base.py", line 279, in ensure_connection
    self.connect()
  File "/Users/krohn/PycharmProjects/DME-AGENTS/dgi-extractor/.venv/lib/python3.12/site-packages/django/utils/asyncio.py", line 26, in inner
    return func(*args, **kwargs)
           ^^^^^^^^^^^^^^^^^^^^^
  File "/Users/krohn/PycharmProjects/DME-AGENTS/dgi-extractor/.venv/lib/python3.12/site-packages/django/db/backends/base/base.py", line 256, in connect
    self.connection = self.get_new_connection(conn_params)
                      ^^^^^^^^^^^^^^^^^^^^^^^^^^^^^^^^^^^^
  File "/Users/krohn/PycharmProjects/DME-AGENTS/dgi-extractor/.venv/lib/python3.12/site-packages/django/utils/asyncio.py", line 26, in inner
    return func(*args, **kwargs)
           ^^^^^^^^^^^^^^^^^^^^^
  File "/Users/krohn/PycharmProjects/DME-AGENTS/dgi-extractor/.venv/lib/python3.12/site-packages/django/db/backends/postgresql/base.py", line 332, in get_new_connection
    connection = self.Database.connect(**conn_params)
                 ^^^^^^^^^^^^^^^^^^^^^^^^^^^^^^^^^^^^
  File "/Users/krohn/PycharmProjects/DME-AGENTS/dgi-extractor/.venv/lib/python3.12/site-packages/psycopg2/__init__.py", line 122, in connect
    conn = _connect(dsn, connection_factory=connection_factory, **kwasync)
           ^^^^^^^^^^^^^^^^^^^^^^^^^^^^^^^^^^^^^^^^^^^^^^^^^^^^^^^^^^^^^^^
django.db.utils.OperationalError: connection to server at "37.60.239.221", port 5433 failed: No route to host
	Is the server running on that host and accepting TCP/IP connections?

ERROR 2025-10-07 05:14:57,288 basehttp 90746 123145573666816 "POST /api/v1/processing/rag/generate/ HTTP/1.1" 500 151794
ERROR 2025-10-07 05:15:38,800 log 90746 123145556877312 Internal Server Error: /api/v1/processing/rag/chat/completions/
Traceback (most recent call last):
  File "/Users/krohn/PycharmProjects/DME-AGENTS/dgi-extractor/.venv/lib/python3.12/site-packages/django/db/backends/base/base.py", line 279, in ensure_connection
    self.connect()
  File "/Users/krohn/PycharmProjects/DME-AGENTS/dgi-extractor/.venv/lib/python3.12/site-packages/django/utils/asyncio.py", line 26, in inner
    return func(*args, **kwargs)
           ^^^^^^^^^^^^^^^^^^^^^
  File "/Users/krohn/PycharmProjects/DME-AGENTS/dgi-extractor/.venv/lib/python3.12/site-packages/django/db/backends/base/base.py", line 256, in connect
    self.connection = self.get_new_connection(conn_params)
                      ^^^^^^^^^^^^^^^^^^^^^^^^^^^^^^^^^^^^
  File "/Users/krohn/PycharmProjects/DME-AGENTS/dgi-extractor/.venv/lib/python3.12/site-packages/django/utils/asyncio.py", line 26, in inner
    return func(*args, **kwargs)
           ^^^^^^^^^^^^^^^^^^^^^
  File "/Users/krohn/PycharmProjects/DME-AGENTS/dgi-extractor/.venv/lib/python3.12/site-packages/django/db/backends/postgresql/base.py", line 332, in get_new_connection
    connection = self.Database.connect(**conn_params)
                 ^^^^^^^^^^^^^^^^^^^^^^^^^^^^^^^^^^^^
  File "/Users/krohn/PycharmProjects/DME-AGENTS/dgi-extractor/.venv/lib/python3.12/site-packages/psycopg2/__init__.py", line 122, in connect
    conn = _connect(dsn, connection_factory=connection_factory, **kwasync)
           ^^^^^^^^^^^^^^^^^^^^^^^^^^^^^^^^^^^^^^^^^^^^^^^^^^^^^^^^^^^^^^^
psycopg2.OperationalError: connection to server at "37.60.239.221", port 5433 failed: Operation timed out
	Is the server running on that host and accepting TCP/IP connections?


The above exception was the direct cause of the following exception:

Traceback (most recent call last):
  File "/Users/krohn/PycharmProjects/DME-AGENTS/dgi-extractor/.venv/lib/python3.12/site-packages/django/core/handlers/exception.py", line 55, in inner
    response = get_response(request)
               ^^^^^^^^^^^^^^^^^^^^^
  File "/Users/krohn/PycharmProjects/DME-AGENTS/dgi-extractor/.venv/lib/python3.12/site-packages/django/core/handlers/base.py", line 197, in _get_response
    response = wrapped_callback(request, *callback_args, **callback_kwargs)
               ^^^^^^^^^^^^^^^^^^^^^^^^^^^^^^^^^^^^^^^^^^^^^^^^^^^^^^^^^^^^
  File "/Library/Frameworks/Python.framework/Versions/3.12/lib/python3.12/contextlib.py", line 80, in inner
    with self._recreate_cm():
         ^^^^^^^^^^^^^^^^^^^
  File "/Users/krohn/PycharmProjects/DME-AGENTS/dgi-extractor/.venv/lib/python3.12/site-packages/django/db/transaction.py", line 198, in __enter__
    if not connection.get_autocommit():
           ^^^^^^^^^^^^^^^^^^^^^^^^^^^
  File "/Users/krohn/PycharmProjects/DME-AGENTS/dgi-extractor/.venv/lib/python3.12/site-packages/django/db/backends/base/base.py", line 454, in get_autocommit
    self.ensure_connection()
  File "/Users/krohn/PycharmProjects/DME-AGENTS/dgi-extractor/.venv/lib/python3.12/site-packages/django/utils/asyncio.py", line 26, in inner
    return func(*args, **kwargs)
           ^^^^^^^^^^^^^^^^^^^^^
  File "/Users/krohn/PycharmProjects/DME-AGENTS/dgi-extractor/.venv/lib/python3.12/site-packages/django/db/backends/base/base.py", line 278, in ensure_connection
    with self.wrap_database_errors:
         ^^^^^^^^^^^^^^^^^^^^^^^^^
  File "/Users/krohn/PycharmProjects/DME-AGENTS/dgi-extractor/.venv/lib/python3.12/site-packages/django/db/utils.py", line 91, in __exit__
    raise dj_exc_value.with_traceback(traceback) from exc_value
  File "/Users/krohn/PycharmProjects/DME-AGENTS/dgi-extractor/.venv/lib/python3.12/site-packages/django/db/backends/base/base.py", line 279, in ensure_connection
    self.connect()
  File "/Users/krohn/PycharmProjects/DME-AGENTS/dgi-extractor/.venv/lib/python3.12/site-packages/django/utils/asyncio.py", line 26, in inner
    return func(*args, **kwargs)
           ^^^^^^^^^^^^^^^^^^^^^
  File "/Users/krohn/PycharmProjects/DME-AGENTS/dgi-extractor/.venv/lib/python3.12/site-packages/django/db/backends/base/base.py", line 256, in connect
    self.connection = self.get_new_connection(conn_params)
                      ^^^^^^^^^^^^^^^^^^^^^^^^^^^^^^^^^^^^
  File "/Users/krohn/PycharmProjects/DME-AGENTS/dgi-extractor/.venv/lib/python3.12/site-packages/django/utils/asyncio.py", line 26, in inner
    return func(*args, **kwargs)
           ^^^^^^^^^^^^^^^^^^^^^
  File "/Users/krohn/PycharmProjects/DME-AGENTS/dgi-extractor/.venv/lib/python3.12/site-packages/django/db/backends/postgresql/base.py", line 332, in get_new_connection
    connection = self.Database.connect(**conn_params)
                 ^^^^^^^^^^^^^^^^^^^^^^^^^^^^^^^^^^^^
  File "/Users/krohn/PycharmProjects/DME-AGENTS/dgi-extractor/.venv/lib/python3.12/site-packages/psycopg2/__init__.py", line 122, in connect
    conn = _connect(dsn, connection_factory=connection_factory, **kwasync)
           ^^^^^^^^^^^^^^^^^^^^^^^^^^^^^^^^^^^^^^^^^^^^^^^^^^^^^^^^^^^^^^^
django.db.utils.OperationalError: connection to server at "37.60.239.221", port 5433 failed: Operation timed out
	Is the server running on that host and accepting TCP/IP connections?

INFO 2025-10-07 05:15:38,812 basehttp 90746 123145556877312 - Broken pipe from ('127.0.0.1', 61996)
ERROR 2025-10-07 05:17:26,370 log 90746 123145489719296 Internal Server Error: /api/v1/public/all-extracted-content/
Traceback (most recent call last):
  File "/Users/krohn/PycharmProjects/DME-AGENTS/dgi-extractor/.venv/lib/python3.12/site-packages/django/db/backends/base/base.py", line 303, in _commit
    return self.connection.commit()
           ^^^^^^^^^^^^^^^^^^^^^^^^
psycopg2.InterfaceError: connection already closed

The above exception was the direct cause of the following exception:

Traceback (most recent call last):
  File "/Users/krohn/PycharmProjects/DME-AGENTS/dgi-extractor/.venv/lib/python3.12/site-packages/django/db/transaction.py", line 263, in __exit__
    connection.commit()
  File "/Users/krohn/PycharmProjects/DME-AGENTS/dgi-extractor/.venv/lib/python3.12/site-packages/django/utils/asyncio.py", line 26, in inner
    return func(*args, **kwargs)
           ^^^^^^^^^^^^^^^^^^^^^
  File "/Users/krohn/PycharmProjects/DME-AGENTS/dgi-extractor/.venv/lib/python3.12/site-packages/django/db/backends/base/base.py", line 327, in commit
    self._commit()
  File "/Users/krohn/PycharmProjects/DME-AGENTS/dgi-extractor/.venv/lib/python3.12/site-packages/django/db/backends/base/base.py", line 302, in _commit
    with debug_transaction(self, "COMMIT"), self.wrap_database_errors:
                                            ^^^^^^^^^^^^^^^^^^^^^^^^^
  File "/Users/krohn/PycharmProjects/DME-AGENTS/dgi-extractor/.venv/lib/python3.12/site-packages/django/db/utils.py", line 91, in __exit__
    raise dj_exc_value.with_traceback(traceback) from exc_value
  File "/Users/krohn/PycharmProjects/DME-AGENTS/dgi-extractor/.venv/lib/python3.12/site-packages/django/db/backends/base/base.py", line 303, in _commit
    return self.connection.commit()
           ^^^^^^^^^^^^^^^^^^^^^^^^
django.db.utils.InterfaceError: connection already closed

During handling of the above exception, another exception occurred:

Traceback (most recent call last):
  File "/Users/krohn/PycharmProjects/DME-AGENTS/dgi-extractor/.venv/lib/python3.12/site-packages/django/db/backends/postgresql/base.py", line 474, in _set_autocommit
    self.connection.autocommit = autocommit
    ^^^^^^^^^^^^^^^^^^^^^^^^^^
psycopg2.InterfaceError: connection already closed

The above exception was the direct cause of the following exception:

Traceback (most recent call last):
  File "/Users/krohn/PycharmProjects/DME-AGENTS/dgi-extractor/.venv/lib/python3.12/site-packages/django/core/handlers/exception.py", line 55, in inner
    response = get_response(request)
               ^^^^^^^^^^^^^^^^^^^^^
  File "/Users/krohn/PycharmProjects/DME-AGENTS/dgi-extractor/.venv/lib/python3.12/site-packages/django/core/handlers/base.py", line 197, in _get_response
    response = wrapped_callback(request, *callback_args, **callback_kwargs)
               ^^^^^^^^^^^^^^^^^^^^^^^^^^^^^^^^^^^^^^^^^^^^^^^^^^^^^^^^^^^^
  File "/Library/Frameworks/Python.framework/Versions/3.12/lib/python3.12/contextlib.py", line 80, in inner
    with self._recreate_cm():
         ^^^^^^^^^^^^^^^^^^^
  File "/Users/krohn/PycharmProjects/DME-AGENTS/dgi-extractor/.venv/lib/python3.12/site-packages/django/db/transaction.py", line 307, in __exit__
    connection.set_autocommit(True)
  File "/Users/krohn/PycharmProjects/DME-AGENTS/dgi-extractor/.venv/lib/python3.12/site-packages/django/db/backends/base/base.py", line 484, in set_autocommit
    self._set_autocommit(autocommit)
  File "/Users/krohn/PycharmProjects/DME-AGENTS/dgi-extractor/.venv/lib/python3.12/site-packages/django/db/backends/postgresql/base.py", line 473, in _set_autocommit
    with self.wrap_database_errors:
         ^^^^^^^^^^^^^^^^^^^^^^^^^
  File "/Users/krohn/PycharmProjects/DME-AGENTS/dgi-extractor/.venv/lib/python3.12/site-packages/django/db/utils.py", line 91, in __exit__
    raise dj_exc_value.with_traceback(traceback) from exc_value
  File "/Users/krohn/PycharmProjects/DME-AGENTS/dgi-extractor/.venv/lib/python3.12/site-packages/django/db/backends/postgresql/base.py", line 474, in _set_autocommit
    self.connection.autocommit = autocommit
    ^^^^^^^^^^^^^^^^^^^^^^^^^^
django.db.utils.InterfaceError: connection already closed
INFO 2025-10-07 05:17:26,378 basehttp 90746 123145489719296 - Broken pipe from ('127.0.0.1', 61911)
ERROR 2025-10-07 05:17:33,339 log 90746 123145556877312 Internal Server Error: /api/v1/processing/rag/chat/completions/
Traceback (most recent call last):
  File "/Users/krohn/PycharmProjects/DME-AGENTS/dgi-extractor/.venv/lib/python3.12/site-packages/django/db/backends/base/base.py", line 279, in ensure_connection
    self.connect()
  File "/Users/krohn/PycharmProjects/DME-AGENTS/dgi-extractor/.venv/lib/python3.12/site-packages/django/utils/asyncio.py", line 26, in inner
    return func(*args, **kwargs)
           ^^^^^^^^^^^^^^^^^^^^^
  File "/Users/krohn/PycharmProjects/DME-AGENTS/dgi-extractor/.venv/lib/python3.12/site-packages/django/db/backends/base/base.py", line 256, in connect
    self.connection = self.get_new_connection(conn_params)
                      ^^^^^^^^^^^^^^^^^^^^^^^^^^^^^^^^^^^^
  File "/Users/krohn/PycharmProjects/DME-AGENTS/dgi-extractor/.venv/lib/python3.12/site-packages/django/utils/asyncio.py", line 26, in inner
    return func(*args, **kwargs)
           ^^^^^^^^^^^^^^^^^^^^^
  File "/Users/krohn/PycharmProjects/DME-AGENTS/dgi-extractor/.venv/lib/python3.12/site-packages/django/db/backends/postgresql/base.py", line 332, in get_new_connection
    connection = self.Database.connect(**conn_params)
                 ^^^^^^^^^^^^^^^^^^^^^^^^^^^^^^^^^^^^
  File "/Users/krohn/PycharmProjects/DME-AGENTS/dgi-extractor/.venv/lib/python3.12/site-packages/psycopg2/__init__.py", line 122, in connect
    conn = _connect(dsn, connection_factory=connection_factory, **kwasync)
           ^^^^^^^^^^^^^^^^^^^^^^^^^^^^^^^^^^^^^^^^^^^^^^^^^^^^^^^^^^^^^^^
psycopg2.OperationalError: connection to server at "37.60.239.221", port 5433 failed: Operation timed out
	Is the server running on that host and accepting TCP/IP connections?


The above exception was the direct cause of the following exception:

Traceback (most recent call last):
  File "/Users/krohn/PycharmProjects/DME-AGENTS/dgi-extractor/.venv/lib/python3.12/site-packages/django/core/handlers/exception.py", line 55, in inner
    response = get_response(request)
               ^^^^^^^^^^^^^^^^^^^^^
  File "/Users/krohn/PycharmProjects/DME-AGENTS/dgi-extractor/.venv/lib/python3.12/site-packages/django/core/handlers/base.py", line 197, in _get_response
    response = wrapped_callback(request, *callback_args, **callback_kwargs)
               ^^^^^^^^^^^^^^^^^^^^^^^^^^^^^^^^^^^^^^^^^^^^^^^^^^^^^^^^^^^^
  File "/Library/Frameworks/Python.framework/Versions/3.12/lib/python3.12/contextlib.py", line 80, in inner
    with self._recreate_cm():
         ^^^^^^^^^^^^^^^^^^^
  File "/Users/krohn/PycharmProjects/DME-AGENTS/dgi-extractor/.venv/lib/python3.12/site-packages/django/db/transaction.py", line 198, in __enter__
    if not connection.get_autocommit():
           ^^^^^^^^^^^^^^^^^^^^^^^^^^^
  File "/Users/krohn/PycharmProjects/DME-AGENTS/dgi-extractor/.venv/lib/python3.12/site-packages/django/db/backends/base/base.py", line 454, in get_autocommit
    self.ensure_connection()
  File "/Users/krohn/PycharmProjects/DME-AGENTS/dgi-extractor/.venv/lib/python3.12/site-packages/django/utils/asyncio.py", line 26, in inner
    return func(*args, **kwargs)
           ^^^^^^^^^^^^^^^^^^^^^
  File "/Users/krohn/PycharmProjects/DME-AGENTS/dgi-extractor/.venv/lib/python3.12/site-packages/django/db/backends/base/base.py", line 278, in ensure_connection
    with self.wrap_database_errors:
         ^^^^^^^^^^^^^^^^^^^^^^^^^
  File "/Users/krohn/PycharmProjects/DME-AGENTS/dgi-extractor/.venv/lib/python3.12/site-packages/django/db/utils.py", line 91, in __exit__
    raise dj_exc_value.with_traceback(traceback) from exc_value
  File "/Users/krohn/PycharmProjects/DME-AGENTS/dgi-extractor/.venv/lib/python3.12/site-packages/django/db/backends/base/base.py", line 279, in ensure_connection
    self.connect()
  File "/Users/krohn/PycharmProjects/DME-AGENTS/dgi-extractor/.venv/lib/python3.12/site-packages/django/utils/asyncio.py", line 26, in inner
    return func(*args, **kwargs)
           ^^^^^^^^^^^^^^^^^^^^^
  File "/Users/krohn/PycharmProjects/DME-AGENTS/dgi-extractor/.venv/lib/python3.12/site-packages/django/db/backends/base/base.py", line 256, in connect
    self.connection = self.get_new_connection(conn_params)
                      ^^^^^^^^^^^^^^^^^^^^^^^^^^^^^^^^^^^^
  File "/Users/krohn/PycharmProjects/DME-AGENTS/dgi-extractor/.venv/lib/python3.12/site-packages/django/utils/asyncio.py", line 26, in inner
    return func(*args, **kwargs)
           ^^^^^^^^^^^^^^^^^^^^^
  File "/Users/krohn/PycharmProjects/DME-AGENTS/dgi-extractor/.venv/lib/python3.12/site-packages/django/db/backends/postgresql/base.py", line 332, in get_new_connection
    connection = self.Database.connect(**conn_params)
                 ^^^^^^^^^^^^^^^^^^^^^^^^^^^^^^^^^^^^
  File "/Users/krohn/PycharmProjects/DME-AGENTS/dgi-extractor/.venv/lib/python3.12/site-packages/psycopg2/__init__.py", line 122, in connect
    conn = _connect(dsn, connection_factory=connection_factory, **kwasync)
           ^^^^^^^^^^^^^^^^^^^^^^^^^^^^^^^^^^^^^^^^^^^^^^^^^^^^^^^^^^^^^^^
django.db.utils.OperationalError: connection to server at "37.60.239.221", port 5433 failed: Operation timed out
	Is the server running on that host and accepting TCP/IP connections?

INFO 2025-10-07 05:17:33,343 basehttp 90746 123145556877312 - Broken pipe from ('127.0.0.1', 64563)
ERROR 2025-10-07 05:18:03,653 log 90746 123145573666816 Internal Server Error: /api/v1/processing/rag/generate/
Traceback (most recent call last):
  File "/Users/krohn/PycharmProjects/DME-AGENTS/dgi-extractor/.venv/lib/python3.12/site-packages/django/db/backends/base/base.py", line 279, in ensure_connection
    self.connect()
  File "/Users/krohn/PycharmProjects/DME-AGENTS/dgi-extractor/.venv/lib/python3.12/site-packages/django/utils/asyncio.py", line 26, in inner
    return func(*args, **kwargs)
           ^^^^^^^^^^^^^^^^^^^^^
  File "/Users/krohn/PycharmProjects/DME-AGENTS/dgi-extractor/.venv/lib/python3.12/site-packages/django/db/backends/base/base.py", line 256, in connect
    self.connection = self.get_new_connection(conn_params)
                      ^^^^^^^^^^^^^^^^^^^^^^^^^^^^^^^^^^^^
  File "/Users/krohn/PycharmProjects/DME-AGENTS/dgi-extractor/.venv/lib/python3.12/site-packages/django/utils/asyncio.py", line 26, in inner
    return func(*args, **kwargs)
           ^^^^^^^^^^^^^^^^^^^^^
  File "/Users/krohn/PycharmProjects/DME-AGENTS/dgi-extractor/.venv/lib/python3.12/site-packages/django/db/backends/postgresql/base.py", line 332, in get_new_connection
    connection = self.Database.connect(**conn_params)
                 ^^^^^^^^^^^^^^^^^^^^^^^^^^^^^^^^^^^^
  File "/Users/krohn/PycharmProjects/DME-AGENTS/dgi-extractor/.venv/lib/python3.12/site-packages/psycopg2/__init__.py", line 122, in connect
    conn = _connect(dsn, connection_factory=connection_factory, **kwasync)
           ^^^^^^^^^^^^^^^^^^^^^^^^^^^^^^^^^^^^^^^^^^^^^^^^^^^^^^^^^^^^^^^
psycopg2.OperationalError: connection to server at "37.60.239.221", port 5433 failed: Operation timed out
	Is the server running on that host and accepting TCP/IP connections?


The above exception was the direct cause of the following exception:

Traceback (most recent call last):
  File "/Users/krohn/PycharmProjects/DME-AGENTS/dgi-extractor/.venv/lib/python3.12/site-packages/django/core/handlers/exception.py", line 55, in inner
    response = get_response(request)
               ^^^^^^^^^^^^^^^^^^^^^
  File "/Users/krohn/PycharmProjects/DME-AGENTS/dgi-extractor/.venv/lib/python3.12/site-packages/django/core/handlers/base.py", line 197, in _get_response
    response = wrapped_callback(request, *callback_args, **callback_kwargs)
               ^^^^^^^^^^^^^^^^^^^^^^^^^^^^^^^^^^^^^^^^^^^^^^^^^^^^^^^^^^^^
  File "/Library/Frameworks/Python.framework/Versions/3.12/lib/python3.12/contextlib.py", line 80, in inner
    with self._recreate_cm():
         ^^^^^^^^^^^^^^^^^^^
  File "/Users/krohn/PycharmProjects/DME-AGENTS/dgi-extractor/.venv/lib/python3.12/site-packages/django/db/transaction.py", line 198, in __enter__
    if not connection.get_autocommit():
           ^^^^^^^^^^^^^^^^^^^^^^^^^^^
  File "/Users/krohn/PycharmProjects/DME-AGENTS/dgi-extractor/.venv/lib/python3.12/site-packages/django/db/backends/base/base.py", line 454, in get_autocommit
    self.ensure_connection()
  File "/Users/krohn/PycharmProjects/DME-AGENTS/dgi-extractor/.venv/lib/python3.12/site-packages/django/utils/asyncio.py", line 26, in inner
    return func(*args, **kwargs)
           ^^^^^^^^^^^^^^^^^^^^^
  File "/Users/krohn/PycharmProjects/DME-AGENTS/dgi-extractor/.venv/lib/python3.12/site-packages/django/db/backends/base/base.py", line 278, in ensure_connection
    with self.wrap_database_errors:
         ^^^^^^^^^^^^^^^^^^^^^^^^^
  File "/Users/krohn/PycharmProjects/DME-AGENTS/dgi-extractor/.venv/lib/python3.12/site-packages/django/db/utils.py", line 91, in __exit__
    raise dj_exc_value.with_traceback(traceback) from exc_value
  File "/Users/krohn/PycharmProjects/DME-AGENTS/dgi-extractor/.venv/lib/python3.12/site-packages/django/db/backends/base/base.py", line 279, in ensure_connection
    self.connect()
  File "/Users/krohn/PycharmProjects/DME-AGENTS/dgi-extractor/.venv/lib/python3.12/site-packages/django/utils/asyncio.py", line 26, in inner
    return func(*args, **kwargs)
           ^^^^^^^^^^^^^^^^^^^^^
  File "/Users/krohn/PycharmProjects/DME-AGENTS/dgi-extractor/.venv/lib/python3.12/site-packages/django/db/backends/base/base.py", line 256, in connect
    self.connection = self.get_new_connection(conn_params)
                      ^^^^^^^^^^^^^^^^^^^^^^^^^^^^^^^^^^^^
  File "/Users/krohn/PycharmProjects/DME-AGENTS/dgi-extractor/.venv/lib/python3.12/site-packages/django/utils/asyncio.py", line 26, in inner
    return func(*args, **kwargs)
           ^^^^^^^^^^^^^^^^^^^^^
  File "/Users/krohn/PycharmProjects/DME-AGENTS/dgi-extractor/.venv/lib/python3.12/site-packages/django/db/backends/postgresql/base.py", line 332, in get_new_connection
    connection = self.Database.connect(**conn_params)
                 ^^^^^^^^^^^^^^^^^^^^^^^^^^^^^^^^^^^^
  File "/Users/krohn/PycharmProjects/DME-AGENTS/dgi-extractor/.venv/lib/python3.12/site-packages/psycopg2/__init__.py", line 122, in connect
    conn = _connect(dsn, connection_factory=connection_factory, **kwasync)
           ^^^^^^^^^^^^^^^^^^^^^^^^^^^^^^^^^^^^^^^^^^^^^^^^^^^^^^^^^^^^^^^
django.db.utils.OperationalError: connection to server at "37.60.239.221", port 5433 failed: Operation timed out
	Is the server running on that host and accepting TCP/IP connections?

INFO 2025-10-07 05:18:03,655 basehttp 90746 123145573666816 - Broken pipe from ('127.0.0.1', 64968)
ERROR 2025-10-07 05:18:46,691 log 90746 123145540087808 Internal Server Error: /api/v1/public/all-extracted-content/
Traceback (most recent call last):
  File "/Users/krohn/PycharmProjects/DME-AGENTS/dgi-extractor/.venv/lib/python3.12/site-packages/django/db/backends/base/base.py", line 303, in _commit
    return self.connection.commit()
           ^^^^^^^^^^^^^^^^^^^^^^^^
psycopg2.InterfaceError: connection already closed

The above exception was the direct cause of the following exception:

Traceback (most recent call last):
  File "/Users/krohn/PycharmProjects/DME-AGENTS/dgi-extractor/.venv/lib/python3.12/site-packages/django/db/transaction.py", line 263, in __exit__
    connection.commit()
  File "/Users/krohn/PycharmProjects/DME-AGENTS/dgi-extractor/.venv/lib/python3.12/site-packages/django/utils/asyncio.py", line 26, in inner
    return func(*args, **kwargs)
           ^^^^^^^^^^^^^^^^^^^^^
  File "/Users/krohn/PycharmProjects/DME-AGENTS/dgi-extractor/.venv/lib/python3.12/site-packages/django/db/backends/base/base.py", line 327, in commit
    self._commit()
  File "/Users/krohn/PycharmProjects/DME-AGENTS/dgi-extractor/.venv/lib/python3.12/site-packages/django/db/backends/base/base.py", line 302, in _commit
    with debug_transaction(self, "COMMIT"), self.wrap_database_errors:
                                            ^^^^^^^^^^^^^^^^^^^^^^^^^
  File "/Users/krohn/PycharmProjects/DME-AGENTS/dgi-extractor/.venv/lib/python3.12/site-packages/django/db/utils.py", line 91, in __exit__
    raise dj_exc_value.with_traceback(traceback) from exc_value
  File "/Users/krohn/PycharmProjects/DME-AGENTS/dgi-extractor/.venv/lib/python3.12/site-packages/django/db/backends/base/base.py", line 303, in _commit
    return self.connection.commit()
           ^^^^^^^^^^^^^^^^^^^^^^^^
django.db.utils.InterfaceError: connection already closed

During handling of the above exception, another exception occurred:

Traceback (most recent call last):
  File "/Users/krohn/PycharmProjects/DME-AGENTS/dgi-extractor/.venv/lib/python3.12/site-packages/django/db/backends/postgresql/base.py", line 474, in _set_autocommit
    self.connection.autocommit = autocommit
    ^^^^^^^^^^^^^^^^^^^^^^^^^^
psycopg2.InterfaceError: connection already closed

The above exception was the direct cause of the following exception:

Traceback (most recent call last):
  File "/Users/krohn/PycharmProjects/DME-AGENTS/dgi-extractor/.venv/lib/python3.12/site-packages/django/core/handlers/exception.py", line 55, in inner
    response = get_response(request)
               ^^^^^^^^^^^^^^^^^^^^^
  File "/Users/krohn/PycharmProjects/DME-AGENTS/dgi-extractor/.venv/lib/python3.12/site-packages/django/core/handlers/base.py", line 197, in _get_response
    response = wrapped_callback(request, *callback_args, **callback_kwargs)
               ^^^^^^^^^^^^^^^^^^^^^^^^^^^^^^^^^^^^^^^^^^^^^^^^^^^^^^^^^^^^
  File "/Library/Frameworks/Python.framework/Versions/3.12/lib/python3.12/contextlib.py", line 80, in inner
    with self._recreate_cm():
         ^^^^^^^^^^^^^^^^^^^
  File "/Users/krohn/PycharmProjects/DME-AGENTS/dgi-extractor/.venv/lib/python3.12/site-packages/django/db/transaction.py", line 307, in __exit__
    connection.set_autocommit(True)
  File "/Users/krohn/PycharmProjects/DME-AGENTS/dgi-extractor/.venv/lib/python3.12/site-packages/django/db/backends/base/base.py", line 484, in set_autocommit
    self._set_autocommit(autocommit)
  File "/Users/krohn/PycharmProjects/DME-AGENTS/dgi-extractor/.venv/lib/python3.12/site-packages/django/db/backends/postgresql/base.py", line 473, in _set_autocommit
    with self.wrap_database_errors:
         ^^^^^^^^^^^^^^^^^^^^^^^^^
  File "/Users/krohn/PycharmProjects/DME-AGENTS/dgi-extractor/.venv/lib/python3.12/site-packages/django/db/utils.py", line 91, in __exit__
    raise dj_exc_value.with_traceback(traceback) from exc_value
  File "/Users/krohn/PycharmProjects/DME-AGENTS/dgi-extractor/.venv/lib/python3.12/site-packages/django/db/backends/postgresql/base.py", line 474, in _set_autocommit
    self.connection.autocommit = autocommit
    ^^^^^^^^^^^^^^^^^^^^^^^^^^
django.db.utils.InterfaceError: connection already closed
INFO 2025-10-07 05:18:46,693 basehttp 90746 123145540087808 - Broken pipe from ('127.0.0.1', 61975)
INFO 2025-10-07 05:21:28,793 basehttp 90746 123145523298304 - Broken pipe from ('127.0.0.1', 61974)
INFO 2025-10-07 05:23:08,817 basehttp 90746 123145489719296 "GET /api/v1/public/all-extracted-content/?page=1&page_size=10 HTTP/1.1" 200 20790
INFO 2025-10-07 05:24:14,473 autoreload 90746 140704670657024 /Users/krohn/PycharmProjects/DME-AGENTS/dgi-extractor/doctrine/services/rag.py changed, reloading.
INFO 2025-10-07 05:24:16,561 autoreload 93870 140704670657024 Watching for file changes with StatReloader
INFO 2025-10-07 05:24:32,538 autoreload 93870 140704670657024 /Users/krohn/PycharmProjects/DME-AGENTS/dgi-extractor/doctrine/services/rag.py changed, reloading.
INFO 2025-10-07 05:24:33,671 autoreload 93955 140704670657024 Watching for file changes with StatReloader
INFO 2025-10-07 05:25:24,487 autoreload 93955 140704670657024 /Users/krohn/PycharmProjects/DME-AGENTS/dgi-extractor/doctrine/services/rag.py changed, reloading.
INFO 2025-10-07 05:25:25,762 autoreload 94099 140704670657024 Watching for file changes with StatReloader
INFO 2025-10-07 05:25:52,661 autoreload 94099 140704670657024 /Users/krohn/PycharmProjects/DME-AGENTS/dgi-extractor/doctrine/services/rag.py changed, reloading.
INFO 2025-10-07 05:25:53,737 autoreload 94179 140704670657024 Watching for file changes with StatReloader
INFO 2025-10-07 05:26:19,722 autoreload 94179 140704670657024 /Users/krohn/PycharmProjects/DME-AGENTS/dgi-extractor/doctrine/services/rag.py changed, reloading.
INFO 2025-10-07 05:26:20,859 autoreload 94258 140704670657024 Watching for file changes with StatReloader
INFO 2025-10-07 05:26:50,528 autoreload 94258 140704670657024 /Users/krohn/PycharmProjects/DME-AGENTS/dgi-extractor/doctrine/services/rag.py changed, reloading.
INFO 2025-10-07 05:26:51,594 autoreload 94352 140704670657024 Watching for file changes with StatReloader
INFO 2025-10-07 05:27:54,620 autoreload 94352 140704670657024 /Users/krohn/PycharmProjects/DME-AGENTS/dgi-extractor/doctrine/services/rag.py changed, reloading.
INFO 2025-10-07 05:27:55,511 autoreload 94481 140704670657024 Watching for file changes with StatReloader
INFO 2025-10-07 05:31:21,491 basehttp 94481 123145411792896 "GET /api/v1/public/all-extracted-content/?page=1&page_size=10 HTTP/1.1" 200 20789
INFO 2025-10-07 05:36:11,556 autoreload 95483 140704670657024 Watching for file changes with StatReloader
INFO 2025-10-07 05:40:50,271 basehttp 95483 123145433821184 "GET /api/v1/public/all-extracted-content/?page=1&page_size=10 HTTP/1.1" 200 20789
INFO 2025-10-07 05:40:59,545 basehttp 95483 123145450610688 "GET /api/v1/public/all-extracted-content/?page=1&page_size=10 HTTP/1.1" 200 20789
ERROR 2025-10-07 05:46:00,940 log 95483 123145467400192 Internal Server Error: /api/v1/processing/rag/chat/completions/
Traceback (most recent call last):
  File "/Users/krohn/PycharmProjects/DME-AGENTS/dgi-extractor/.venv/lib/python3.12/site-packages/django/db/backends/base/base.py", line 279, in ensure_connection
    self.connect()
  File "/Users/krohn/PycharmProjects/DME-AGENTS/dgi-extractor/.venv/lib/python3.12/site-packages/django/utils/asyncio.py", line 26, in inner
    return func(*args, **kwargs)
           ^^^^^^^^^^^^^^^^^^^^^
  File "/Users/krohn/PycharmProjects/DME-AGENTS/dgi-extractor/.venv/lib/python3.12/site-packages/django/db/backends/base/base.py", line 256, in connect
    self.connection = self.get_new_connection(conn_params)
                      ^^^^^^^^^^^^^^^^^^^^^^^^^^^^^^^^^^^^
  File "/Users/krohn/PycharmProjects/DME-AGENTS/dgi-extractor/.venv/lib/python3.12/site-packages/django/utils/asyncio.py", line 26, in inner
    return func(*args, **kwargs)
           ^^^^^^^^^^^^^^^^^^^^^
  File "/Users/krohn/PycharmProjects/DME-AGENTS/dgi-extractor/.venv/lib/python3.12/site-packages/django/db/backends/postgresql/base.py", line 332, in get_new_connection
    connection = self.Database.connect(**conn_params)
                 ^^^^^^^^^^^^^^^^^^^^^^^^^^^^^^^^^^^^
  File "/Users/krohn/PycharmProjects/DME-AGENTS/dgi-extractor/.venv/lib/python3.12/site-packages/psycopg2/__init__.py", line 122, in connect
    conn = _connect(dsn, connection_factory=connection_factory, **kwasync)
           ^^^^^^^^^^^^^^^^^^^^^^^^^^^^^^^^^^^^^^^^^^^^^^^^^^^^^^^^^^^^^^^
psycopg2.OperationalError: connection to server at "37.60.239.221", port 5433 failed: FATAL:  the database system is in recovery mode


The above exception was the direct cause of the following exception:

Traceback (most recent call last):
  File "/Users/krohn/PycharmProjects/DME-AGENTS/dgi-extractor/.venv/lib/python3.12/site-packages/django/core/handlers/exception.py", line 55, in inner
    response = get_response(request)
               ^^^^^^^^^^^^^^^^^^^^^
  File "/Users/krohn/PycharmProjects/DME-AGENTS/dgi-extractor/.venv/lib/python3.12/site-packages/django/core/handlers/base.py", line 197, in _get_response
    response = wrapped_callback(request, *callback_args, **callback_kwargs)
               ^^^^^^^^^^^^^^^^^^^^^^^^^^^^^^^^^^^^^^^^^^^^^^^^^^^^^^^^^^^^
  File "/Library/Frameworks/Python.framework/Versions/3.12/lib/python3.12/contextlib.py", line 80, in inner
    with self._recreate_cm():
         ^^^^^^^^^^^^^^^^^^^
  File "/Users/krohn/PycharmProjects/DME-AGENTS/dgi-extractor/.venv/lib/python3.12/site-packages/django/db/transaction.py", line 198, in __enter__
    if not connection.get_autocommit():
           ^^^^^^^^^^^^^^^^^^^^^^^^^^^
  File "/Users/krohn/PycharmProjects/DME-AGENTS/dgi-extractor/.venv/lib/python3.12/site-packages/django/db/backends/base/base.py", line 454, in get_autocommit
    self.ensure_connection()
  File "/Users/krohn/PycharmProjects/DME-AGENTS/dgi-extractor/.venv/lib/python3.12/site-packages/django/utils/asyncio.py", line 26, in inner
    return func(*args, **kwargs)
           ^^^^^^^^^^^^^^^^^^^^^
  File "/Users/krohn/PycharmProjects/DME-AGENTS/dgi-extractor/.venv/lib/python3.12/site-packages/django/db/backends/base/base.py", line 278, in ensure_connection
    with self.wrap_database_errors:
         ^^^^^^^^^^^^^^^^^^^^^^^^^
  File "/Users/krohn/PycharmProjects/DME-AGENTS/dgi-extractor/.venv/lib/python3.12/site-packages/django/db/utils.py", line 91, in __exit__
    raise dj_exc_value.with_traceback(traceback) from exc_value
  File "/Users/krohn/PycharmProjects/DME-AGENTS/dgi-extractor/.venv/lib/python3.12/site-packages/django/db/backends/base/base.py", line 279, in ensure_connection
    self.connect()
  File "/Users/krohn/PycharmProjects/DME-AGENTS/dgi-extractor/.venv/lib/python3.12/site-packages/django/utils/asyncio.py", line 26, in inner
    return func(*args, **kwargs)
           ^^^^^^^^^^^^^^^^^^^^^
  File "/Users/krohn/PycharmProjects/DME-AGENTS/dgi-extractor/.venv/lib/python3.12/site-packages/django/db/backends/base/base.py", line 256, in connect
    self.connection = self.get_new_connection(conn_params)
                      ^^^^^^^^^^^^^^^^^^^^^^^^^^^^^^^^^^^^
  File "/Users/krohn/PycharmProjects/DME-AGENTS/dgi-extractor/.venv/lib/python3.12/site-packages/django/utils/asyncio.py", line 26, in inner
    return func(*args, **kwargs)
           ^^^^^^^^^^^^^^^^^^^^^
  File "/Users/krohn/PycharmProjects/DME-AGENTS/dgi-extractor/.venv/lib/python3.12/site-packages/django/db/backends/postgresql/base.py", line 332, in get_new_connection
    connection = self.Database.connect(**conn_params)
                 ^^^^^^^^^^^^^^^^^^^^^^^^^^^^^^^^^^^^
  File "/Users/krohn/PycharmProjects/DME-AGENTS/dgi-extractor/.venv/lib/python3.12/site-packages/psycopg2/__init__.py", line 122, in connect
    conn = _connect(dsn, connection_factory=connection_factory, **kwasync)
           ^^^^^^^^^^^^^^^^^^^^^^^^^^^^^^^^^^^^^^^^^^^^^^^^^^^^^^^^^^^^^^^
django.db.utils.OperationalError: connection to server at "37.60.239.221", port 5433 failed: FATAL:  the database system is in recovery mode

ERROR 2025-10-07 05:46:00,951 basehttp 95483 123145467400192 "POST /api/v1/processing/rag/chat/completions/ HTTP/1.1" 500 151557
INFO 2025-10-07 05:47:33,939 basehttp 95483 123145535152128 "GET /api/v1/public/all-extracted-content/?page=1&page_size=10 HTTP/1.1" 200 20789
INFO 2025-10-07 05:54:04,895 basehttp 95483 123145484189696 - Broken pipe from ('127.0.0.1', 52177)
INFO 2025-10-07 05:54:05,164 basehttp 95483 123145568731136 - Broken pipe from ('127.0.0.1', 52362)
ERROR 2025-10-07 05:54:05,237 log 95483 123145551941632 Internal Server Error: /api/v1/processing/rag/chat/completions/
INFO 2025-10-07 05:54:05,238 basehttp 95483 123145551941632 - Broken pipe from ('127.0.0.1', 52332)
ERROR 2025-10-07 05:54:19,510 log 95483 123145639358464 Internal Server Error: /o/token/
Traceback (most recent call last):
  File "/Users/krohn/PycharmProjects/DME-AGENTS/dgi-extractor/.venv/lib/python3.12/site-packages/django/db/backends/base/base.py", line 279, in ensure_connection
    self.connect()
  File "/Users/krohn/PycharmProjects/DME-AGENTS/dgi-extractor/.venv/lib/python3.12/site-packages/django/utils/asyncio.py", line 26, in inner
    return func(*args, **kwargs)
           ^^^^^^^^^^^^^^^^^^^^^
  File "/Users/krohn/PycharmProjects/DME-AGENTS/dgi-extractor/.venv/lib/python3.12/site-packages/django/db/backends/base/base.py", line 256, in connect
    self.connection = self.get_new_connection(conn_params)
                      ^^^^^^^^^^^^^^^^^^^^^^^^^^^^^^^^^^^^
  File "/Users/krohn/PycharmProjects/DME-AGENTS/dgi-extractor/.venv/lib/python3.12/site-packages/django/utils/asyncio.py", line 26, in inner
    return func(*args, **kwargs)
           ^^^^^^^^^^^^^^^^^^^^^
  File "/Users/krohn/PycharmProjects/DME-AGENTS/dgi-extractor/.venv/lib/python3.12/site-packages/django/db/backends/postgresql/base.py", line 332, in get_new_connection
    connection = self.Database.connect(**conn_params)
                 ^^^^^^^^^^^^^^^^^^^^^^^^^^^^^^^^^^^^
  File "/Users/krohn/PycharmProjects/DME-AGENTS/dgi-extractor/.venv/lib/python3.12/site-packages/psycopg2/__init__.py", line 122, in connect
    conn = _connect(dsn, connection_factory=connection_factory, **kwasync)
           ^^^^^^^^^^^^^^^^^^^^^^^^^^^^^^^^^^^^^^^^^^^^^^^^^^^^^^^^^^^^^^^
psycopg2.OperationalError: connection to server at "37.60.239.221", port 5433 failed: Operation timed out
	Is the server running on that host and accepting TCP/IP connections?


The above exception was the direct cause of the following exception:

Traceback (most recent call last):
  File "/Users/krohn/PycharmProjects/DME-AGENTS/dgi-extractor/.venv/lib/python3.12/site-packages/django/core/handlers/exception.py", line 55, in inner
    response = get_response(request)
               ^^^^^^^^^^^^^^^^^^^^^
  File "/Users/krohn/PycharmProjects/DME-AGENTS/dgi-extractor/.venv/lib/python3.12/site-packages/django/core/handlers/base.py", line 197, in _get_response
    response = wrapped_callback(request, *callback_args, **callback_kwargs)
               ^^^^^^^^^^^^^^^^^^^^^^^^^^^^^^^^^^^^^^^^^^^^^^^^^^^^^^^^^^^^
  File "/Library/Frameworks/Python.framework/Versions/3.12/lib/python3.12/contextlib.py", line 80, in inner
    with self._recreate_cm():
         ^^^^^^^^^^^^^^^^^^^
  File "/Users/krohn/PycharmProjects/DME-AGENTS/dgi-extractor/.venv/lib/python3.12/site-packages/django/db/transaction.py", line 198, in __enter__
    if not connection.get_autocommit():
           ^^^^^^^^^^^^^^^^^^^^^^^^^^^
  File "/Users/krohn/PycharmProjects/DME-AGENTS/dgi-extractor/.venv/lib/python3.12/site-packages/django/db/backends/base/base.py", line 454, in get_autocommit
    self.ensure_connection()
  File "/Users/krohn/PycharmProjects/DME-AGENTS/dgi-extractor/.venv/lib/python3.12/site-packages/django/utils/asyncio.py", line 26, in inner
    return func(*args, **kwargs)
           ^^^^^^^^^^^^^^^^^^^^^
  File "/Users/krohn/PycharmProjects/DME-AGENTS/dgi-extractor/.venv/lib/python3.12/site-packages/django/db/backends/base/base.py", line 278, in ensure_connection
    with self.wrap_database_errors:
         ^^^^^^^^^^^^^^^^^^^^^^^^^
  File "/Users/krohn/PycharmProjects/DME-AGENTS/dgi-extractor/.venv/lib/python3.12/site-packages/django/db/utils.py", line 91, in __exit__
    raise dj_exc_value.with_traceback(traceback) from exc_value
  File "/Users/krohn/PycharmProjects/DME-AGENTS/dgi-extractor/.venv/lib/python3.12/site-packages/django/db/backends/base/base.py", line 279, in ensure_connection
    self.connect()
  File "/Users/krohn/PycharmProjects/DME-AGENTS/dgi-extractor/.venv/lib/python3.12/site-packages/django/utils/asyncio.py", line 26, in inner
    return func(*args, **kwargs)
           ^^^^^^^^^^^^^^^^^^^^^
  File "/Users/krohn/PycharmProjects/DME-AGENTS/dgi-extractor/.venv/lib/python3.12/site-packages/django/db/backends/base/base.py", line 256, in connect
    self.connection = self.get_new_connection(conn_params)
                      ^^^^^^^^^^^^^^^^^^^^^^^^^^^^^^^^^^^^
  File "/Users/krohn/PycharmProjects/DME-AGENTS/dgi-extractor/.venv/lib/python3.12/site-packages/django/utils/asyncio.py", line 26, in inner
    return func(*args, **kwargs)
           ^^^^^^^^^^^^^^^^^^^^^
  File "/Users/krohn/PycharmProjects/DME-AGENTS/dgi-extractor/.venv/lib/python3.12/site-packages/django/db/backends/postgresql/base.py", line 332, in get_new_connection
    connection = self.Database.connect(**conn_params)
                 ^^^^^^^^^^^^^^^^^^^^^^^^^^^^^^^^^^^^
  File "/Users/krohn/PycharmProjects/DME-AGENTS/dgi-extractor/.venv/lib/python3.12/site-packages/psycopg2/__init__.py", line 122, in connect
    conn = _connect(dsn, connection_factory=connection_factory, **kwasync)
           ^^^^^^^^^^^^^^^^^^^^^^^^^^^^^^^^^^^^^^^^^^^^^^^^^^^^^^^^^^^^^^^
django.db.utils.OperationalError: connection to server at "37.60.239.221", port 5433 failed: Operation timed out
	Is the server running on that host and accepting TCP/IP connections?

ERROR 2025-10-07 05:54:19,517 basehttp 95483 123145639358464 "POST /o/token/ HTTP/1.1" 500 154141
INFO 2025-10-07 05:54:48,919 autoreload 98179 140704670657024 Watching for file changes with StatReloader
INFO 2025-10-07 06:02:18,703 autoreload 98928 140704670657024 Watching for file changes with StatReloader
ERROR 2025-10-07 06:02:34,131 log 98928 123145571250176 Internal Server Error: /api/v1/public/all-extracted-content/
Traceback (most recent call last):
  File "/Users/krohn/PycharmProjects/DME-AGENTS/dgi-extractor/.venv/lib/python3.12/site-packages/django/db/backends/base/base.py", line 279, in ensure_connection
    self.connect()
  File "/Users/krohn/PycharmProjects/DME-AGENTS/dgi-extractor/.venv/lib/python3.12/site-packages/django/utils/asyncio.py", line 26, in inner
    return func(*args, **kwargs)
           ^^^^^^^^^^^^^^^^^^^^^
  File "/Users/krohn/PycharmProjects/DME-AGENTS/dgi-extractor/.venv/lib/python3.12/site-packages/django/db/backends/base/base.py", line 256, in connect
    self.connection = self.get_new_connection(conn_params)
                      ^^^^^^^^^^^^^^^^^^^^^^^^^^^^^^^^^^^^
  File "/Users/krohn/PycharmProjects/DME-AGENTS/dgi-extractor/.venv/lib/python3.12/site-packages/django/utils/asyncio.py", line 26, in inner
    return func(*args, **kwargs)
           ^^^^^^^^^^^^^^^^^^^^^
  File "/Users/krohn/PycharmProjects/DME-AGENTS/dgi-extractor/.venv/lib/python3.12/site-packages/django/db/backends/postgresql/base.py", line 332, in get_new_connection
    connection = self.Database.connect(**conn_params)
                 ^^^^^^^^^^^^^^^^^^^^^^^^^^^^^^^^^^^^
  File "/Users/krohn/PycharmProjects/DME-AGENTS/dgi-extractor/.venv/lib/python3.12/site-packages/psycopg2/__init__.py", line 122, in connect
    conn = _connect(dsn, connection_factory=connection_factory, **kwasync)
           ^^^^^^^^^^^^^^^^^^^^^^^^^^^^^^^^^^^^^^^^^^^^^^^^^^^^^^^^^^^^^^^
psycopg2.OperationalError: connection to server at "37.60.239.221", port 5433 failed: FATAL:  the database system is in recovery mode


The above exception was the direct cause of the following exception:

Traceback (most recent call last):
  File "/Users/krohn/PycharmProjects/DME-AGENTS/dgi-extractor/.venv/lib/python3.12/site-packages/django/core/handlers/exception.py", line 55, in inner
    response = get_response(request)
               ^^^^^^^^^^^^^^^^^^^^^
  File "/Users/krohn/PycharmProjects/DME-AGENTS/dgi-extractor/.venv/lib/python3.12/site-packages/django/core/handlers/base.py", line 197, in _get_response
    response = wrapped_callback(request, *callback_args, **callback_kwargs)
               ^^^^^^^^^^^^^^^^^^^^^^^^^^^^^^^^^^^^^^^^^^^^^^^^^^^^^^^^^^^^
  File "/Library/Frameworks/Python.framework/Versions/3.12/lib/python3.12/contextlib.py", line 80, in inner
    with self._recreate_cm():
         ^^^^^^^^^^^^^^^^^^^
  File "/Users/krohn/PycharmProjects/DME-AGENTS/dgi-extractor/.venv/lib/python3.12/site-packages/django/db/transaction.py", line 198, in __enter__
    if not connection.get_autocommit():
           ^^^^^^^^^^^^^^^^^^^^^^^^^^^
  File "/Users/krohn/PycharmProjects/DME-AGENTS/dgi-extractor/.venv/lib/python3.12/site-packages/django/db/backends/base/base.py", line 454, in get_autocommit
    self.ensure_connection()
  File "/Users/krohn/PycharmProjects/DME-AGENTS/dgi-extractor/.venv/lib/python3.12/site-packages/django/utils/asyncio.py", line 26, in inner
    return func(*args, **kwargs)
           ^^^^^^^^^^^^^^^^^^^^^
  File "/Users/krohn/PycharmProjects/DME-AGENTS/dgi-extractor/.venv/lib/python3.12/site-packages/django/db/backends/base/base.py", line 278, in ensure_connection
    with self.wrap_database_errors:
         ^^^^^^^^^^^^^^^^^^^^^^^^^
  File "/Users/krohn/PycharmProjects/DME-AGENTS/dgi-extractor/.venv/lib/python3.12/site-packages/django/db/utils.py", line 91, in __exit__
    raise dj_exc_value.with_traceback(traceback) from exc_value
  File "/Users/krohn/PycharmProjects/DME-AGENTS/dgi-extractor/.venv/lib/python3.12/site-packages/django/db/backends/base/base.py", line 279, in ensure_connection
    self.connect()
  File "/Users/krohn/PycharmProjects/DME-AGENTS/dgi-extractor/.venv/lib/python3.12/site-packages/django/utils/asyncio.py", line 26, in inner
    return func(*args, **kwargs)
           ^^^^^^^^^^^^^^^^^^^^^
  File "/Users/krohn/PycharmProjects/DME-AGENTS/dgi-extractor/.venv/lib/python3.12/site-packages/django/db/backends/base/base.py", line 256, in connect
    self.connection = self.get_new_connection(conn_params)
                      ^^^^^^^^^^^^^^^^^^^^^^^^^^^^^^^^^^^^
  File "/Users/krohn/PycharmProjects/DME-AGENTS/dgi-extractor/.venv/lib/python3.12/site-packages/django/utils/asyncio.py", line 26, in inner
    return func(*args, **kwargs)
           ^^^^^^^^^^^^^^^^^^^^^
  File "/Users/krohn/PycharmProjects/DME-AGENTS/dgi-extractor/.venv/lib/python3.12/site-packages/django/db/backends/postgresql/base.py", line 332, in get_new_connection
    connection = self.Database.connect(**conn_params)
                 ^^^^^^^^^^^^^^^^^^^^^^^^^^^^^^^^^^^^
  File "/Users/krohn/PycharmProjects/DME-AGENTS/dgi-extractor/.venv/lib/python3.12/site-packages/psycopg2/__init__.py", line 122, in connect
    conn = _connect(dsn, connection_factory=connection_factory, **kwasync)
           ^^^^^^^^^^^^^^^^^^^^^^^^^^^^^^^^^^^^^^^^^^^^^^^^^^^^^^^^^^^^^^^
django.db.utils.OperationalError: connection to server at "37.60.239.221", port 5433 failed: FATAL:  the database system is in recovery mode

ERROR 2025-10-07 06:02:34,181 basehttp 98928 123145571250176 "GET /api/v1/public/all-extracted-content/?page=1&page_size=10 HTTP/1.1" 500 153320
INFO 2025-10-07 06:02:46,050 basehttp 98928 123145588039680 "GET /api/v1/public/all-extracted-content/?page=1&page_size=10 HTTP/1.1" 200 20789
INFO 2025-10-07 06:05:52,858 basehttp 98928 123145723580416 - Broken pipe from ('127.0.0.1', 56852)
INFO 2025-10-07 06:06:25,849 autoreload 99807 140704670657024 Watching for file changes with StatReloader
INFO 2025-10-07 06:06:49,943 basehttp 99807 123145408057344 "GET /admin/ HTTP/1.1" 302 0
INFO 2025-10-07 06:06:49,986 basehttp 99807 123145408057344 "GET /admin/login/?next=/admin/ HTTP/1.1" 200 4170
ERROR 2025-10-07 06:07:42,159 log 99807 123145408057344 Service Unavailable: /api/v1/processing/rag/query/
INFO 2025-10-07 06:07:42,160 basehttp 99807 123145408057344 - Broken pipe from ('127.0.0.1', 57060)
INFO 2025-10-07 06:07:51,471 basehttp 99807 123145408057344 "GET /api/v1/public/all-extracted-content/?page=1&page_size=10 HTTP/1.1" 200 20789
ERROR 2025-10-07 06:09:30,860 log 99807 123145443782656 Service Unavailable: /api/v1/processing/rag/query/
INFO 2025-10-07 06:09:30,872 basehttp 99807 123145443782656 - Broken pipe from ('127.0.0.1', 57156)
INFO 2025-10-07 06:10:31,043 basehttp 99807 123145600946176 "GET /api/v1/processing/rag/models/info/ HTTP/1.1" 200 209
INFO 2025-10-07 06:10:31,043 basehttp 99807 123145600946176 - Broken pipe from ('127.0.0.1', 57350)
INFO 2025-10-07 06:12:02,934 autoreload 99807 140704670657024 /Users/krohn/PycharmProjects/DME-AGENTS/dgi-extractor/core/settings.py changed, reloading.
INFO 2025-10-07 06:12:06,682 autoreload 1046 140704670657024 Watching for file changes with StatReloader
INFO 2025-10-07 06:17:26,872 autoreload 1046 140704670657024 /Users/krohn/PycharmProjects/DME-AGENTS/dgi-extractor/doctrine/services/rag.py changed, reloading.
INFO 2025-10-07 06:17:28,334 autoreload 1928 140704670657024 Watching for file changes with StatReloader
INFO 2025-10-07 06:17:59,963 autoreload 1928 140704670657024 /Users/krohn/PycharmProjects/DME-AGENTS/dgi-extractor/doctrine/services/rag.py changed, reloading.
INFO 2025-10-07 06:18:00,869 autoreload 2010 140704670657024 Watching for file changes with StatReloader
INFO 2025-10-07 06:20:36,484 autoreload 2010 140704670657024 /Users/krohn/PycharmProjects/DME-AGENTS/dgi-extractor/doctrine/services/rag.py changed, reloading.
INFO 2025-10-07 06:20:37,617 autoreload 2445 140704670657024 Watching for file changes with StatReloader
INFO 2025-10-07 06:24:06,788 autoreload 2445 140704670657024 /Users/krohn/PycharmProjects/DME-AGENTS/dgi-extractor/doctrine/services/rag.py changed, reloading.
INFO 2025-10-07 06:24:08,149 autoreload 2748 140704670657024 Watching for file changes with StatReloader
INFO 2025-10-07 06:25:00,493 autoreload 2748 140704670657024 /Users/krohn/PycharmProjects/DME-AGENTS/dgi-extractor/doctrine/services/rag.py changed, reloading.
INFO 2025-10-07 06:25:01,773 autoreload 2858 140704670657024 Watching for file changes with StatReloader
INFO 2025-10-07 06:28:24,902 basehttp 2858 123145569656832 "GET /api/v1/public/all-extracted-content/?page=1&page_size=10 HTTP/1.1" 200 20790
INFO 2025-10-07 06:33:37,697 basehttp 2858 123145603235840 - Broken pipe from ('127.0.0.1', 59958)
ERROR 2025-10-07 06:34:27,695 log 2858 123145569656832 Internal Server Error: /api/v1/processing/rag/chat/completions/
INFO 2025-10-07 06:34:27,696 basehttp 2858 123145569656832 - Broken pipe from ('127.0.0.1', 59923)
INFO 2025-10-07 06:34:27,750 basehttp 2858 123145586446336 - Broken pipe from ('127.0.0.1', 59957)
ERROR 2025-10-07 06:34:38,169 log 2858 123145621635072 Internal Server Error: /api/v1/processing/rag/chat/completions/
ERROR 2025-10-07 06:34:38,170 basehttp 2858 123145621635072 "POST /api/v1/processing/rag/chat/completions/ HTTP/1.1" 500 111
INFO 2025-10-07 06:35:06,100 basehttp 2858 123145569120256 "POST /api/v1/processing/rag/generate/ HTTP/1.1" 200 263
ERROR 2025-10-07 06:35:15,395 log 2858 123145603235840 Internal Server Error: /api/v1/public/all-extracted-content/
Traceback (most recent call last):
  File "/Users/krohn/PycharmProjects/DME-AGENTS/dgi-extractor/.venv/lib/python3.12/site-packages/django/db/backends/base/base.py", line 303, in _commit
    return self.connection.commit()
           ^^^^^^^^^^^^^^^^^^^^^^^^
psycopg2.OperationalError: server closed the connection unexpectedly
	This probably means the server terminated abnormally
	before or while processing the request.


The above exception was the direct cause of the following exception:

Traceback (most recent call last):
  File "/Users/krohn/PycharmProjects/DME-AGENTS/dgi-extractor/.venv/lib/python3.12/site-packages/django/core/handlers/exception.py", line 55, in inner
    response = get_response(request)
               ^^^^^^^^^^^^^^^^^^^^^
  File "/Users/krohn/PycharmProjects/DME-AGENTS/dgi-extractor/.venv/lib/python3.12/site-packages/django/core/handlers/base.py", line 197, in _get_response
    response = wrapped_callback(request, *callback_args, **callback_kwargs)
               ^^^^^^^^^^^^^^^^^^^^^^^^^^^^^^^^^^^^^^^^^^^^^^^^^^^^^^^^^^^^
  File "/Library/Frameworks/Python.framework/Versions/3.12/lib/python3.12/contextlib.py", line 80, in inner
    with self._recreate_cm():
         ^^^^^^^^^^^^^^^^^^^
  File "/Users/krohn/PycharmProjects/DME-AGENTS/dgi-extractor/.venv/lib/python3.12/site-packages/django/db/transaction.py", line 263, in __exit__
    connection.commit()
  File "/Users/krohn/PycharmProjects/DME-AGENTS/dgi-extractor/.venv/lib/python3.12/site-packages/django/utils/asyncio.py", line 26, in inner
    return func(*args, **kwargs)
           ^^^^^^^^^^^^^^^^^^^^^
  File "/Users/krohn/PycharmProjects/DME-AGENTS/dgi-extractor/.venv/lib/python3.12/site-packages/django/db/backends/base/base.py", line 327, in commit
    self._commit()
  File "/Users/krohn/PycharmProjects/DME-AGENTS/dgi-extractor/.venv/lib/python3.12/site-packages/django/db/backends/base/base.py", line 302, in _commit
    with debug_transaction(self, "COMMIT"), self.wrap_database_errors:
                                            ^^^^^^^^^^^^^^^^^^^^^^^^^
  File "/Users/krohn/PycharmProjects/DME-AGENTS/dgi-extractor/.venv/lib/python3.12/site-packages/django/db/utils.py", line 91, in __exit__
    raise dj_exc_value.with_traceback(traceback) from exc_value
  File "/Users/krohn/PycharmProjects/DME-AGENTS/dgi-extractor/.venv/lib/python3.12/site-packages/django/db/backends/base/base.py", line 303, in _commit
    return self.connection.commit()
           ^^^^^^^^^^^^^^^^^^^^^^^^
django.db.utils.OperationalError: server closed the connection unexpectedly
	This probably means the server terminated abnormally
	before or while processing the request.

ERROR 2025-10-07 06:35:15,398 basehttp 2858 123145603235840 "GET /api/v1/public/all-extracted-content/?page=1&page_size=10 HTTP/1.1" 500 108482
ERROR 2025-10-07 06:36:34,586 log 2858 123145569120256 Internal Server Error: /api/v1/processing/rag/chat/completions/
ERROR 2025-10-07 06:36:34,587 basehttp 2858 123145569120256 "POST /api/v1/processing/rag/chat/completions/ HTTP/1.1" 500 111
INFO 2025-10-07 06:37:01,407 basehttp 2858 123145585909760 "POST /api/v1/processing/rag/generate/ HTTP/1.1" 200 263
INFO 2025-10-07 06:37:08,519 autoreload 2858 140704670657024 /Users/krohn/PycharmProjects/DME-AGENTS/dgi-extractor/doctrine/services/huggingface_rag.py changed, reloading.
INFO 2025-10-07 06:37:12,242 autoreload 4352 140704670657024 Watching for file changes with StatReloader
ERROR 2025-10-07 06:42:12,585 log 4352 123145531015168 Internal Server Error: /api/v1/processing/rag/query/
Traceback (most recent call last):
  File "/Users/krohn/PycharmProjects/DME-AGENTS/dgi-extractor/.venv/lib/python3.12/site-packages/django/db/backends/base/base.py", line 303, in _commit
    return self.connection.commit()
           ^^^^^^^^^^^^^^^^^^^^^^^^
psycopg2.InterfaceError: connection already closed

The above exception was the direct cause of the following exception:

Traceback (most recent call last):
  File "/Users/krohn/PycharmProjects/DME-AGENTS/dgi-extractor/.venv/lib/python3.12/site-packages/django/db/transaction.py", line 263, in __exit__
    connection.commit()
  File "/Users/krohn/PycharmProjects/DME-AGENTS/dgi-extractor/.venv/lib/python3.12/site-packages/django/utils/asyncio.py", line 26, in inner
    return func(*args, **kwargs)
           ^^^^^^^^^^^^^^^^^^^^^
  File "/Users/krohn/PycharmProjects/DME-AGENTS/dgi-extractor/.venv/lib/python3.12/site-packages/django/db/backends/base/base.py", line 327, in commit
    self._commit()
  File "/Users/krohn/PycharmProjects/DME-AGENTS/dgi-extractor/.venv/lib/python3.12/site-packages/django/db/backends/base/base.py", line 302, in _commit
    with debug_transaction(self, "COMMIT"), self.wrap_database_errors:
                                            ^^^^^^^^^^^^^^^^^^^^^^^^^
  File "/Users/krohn/PycharmProjects/DME-AGENTS/dgi-extractor/.venv/lib/python3.12/site-packages/django/db/utils.py", line 91, in __exit__
    raise dj_exc_value.with_traceback(traceback) from exc_value
  File "/Users/krohn/PycharmProjects/DME-AGENTS/dgi-extractor/.venv/lib/python3.12/site-packages/django/db/backends/base/base.py", line 303, in _commit
    return self.connection.commit()
           ^^^^^^^^^^^^^^^^^^^^^^^^
django.db.utils.InterfaceError: connection already closed

During handling of the above exception, another exception occurred:

Traceback (most recent call last):
  File "/Users/krohn/PycharmProjects/DME-AGENTS/dgi-extractor/.venv/lib/python3.12/site-packages/django/db/backends/postgresql/base.py", line 474, in _set_autocommit
    self.connection.autocommit = autocommit
    ^^^^^^^^^^^^^^^^^^^^^^^^^^
psycopg2.InterfaceError: connection already closed

The above exception was the direct cause of the following exception:

Traceback (most recent call last):
  File "/Users/krohn/PycharmProjects/DME-AGENTS/dgi-extractor/.venv/lib/python3.12/site-packages/django/core/handlers/exception.py", line 55, in inner
    response = get_response(request)
               ^^^^^^^^^^^^^^^^^^^^^
  File "/Users/krohn/PycharmProjects/DME-AGENTS/dgi-extractor/.venv/lib/python3.12/site-packages/django/core/handlers/base.py", line 197, in _get_response
    response = wrapped_callback(request, *callback_args, **callback_kwargs)
               ^^^^^^^^^^^^^^^^^^^^^^^^^^^^^^^^^^^^^^^^^^^^^^^^^^^^^^^^^^^^
  File "/Library/Frameworks/Python.framework/Versions/3.12/lib/python3.12/contextlib.py", line 80, in inner
    with self._recreate_cm():
         ^^^^^^^^^^^^^^^^^^^
  File "/Users/krohn/PycharmProjects/DME-AGENTS/dgi-extractor/.venv/lib/python3.12/site-packages/django/db/transaction.py", line 307, in __exit__
    connection.set_autocommit(True)
  File "/Users/krohn/PycharmProjects/DME-AGENTS/dgi-extractor/.venv/lib/python3.12/site-packages/django/db/backends/base/base.py", line 484, in set_autocommit
    self._set_autocommit(autocommit)
  File "/Users/krohn/PycharmProjects/DME-AGENTS/dgi-extractor/.venv/lib/python3.12/site-packages/django/db/backends/postgresql/base.py", line 473, in _set_autocommit
    with self.wrap_database_errors:
         ^^^^^^^^^^^^^^^^^^^^^^^^^
  File "/Users/krohn/PycharmProjects/DME-AGENTS/dgi-extractor/.venv/lib/python3.12/site-packages/django/db/utils.py", line 91, in __exit__
    raise dj_exc_value.with_traceback(traceback) from exc_value
  File "/Users/krohn/PycharmProjects/DME-AGENTS/dgi-extractor/.venv/lib/python3.12/site-packages/django/db/backends/postgresql/base.py", line 474, in _set_autocommit
    self.connection.autocommit = autocommit
    ^^^^^^^^^^^^^^^^^^^^^^^^^^
django.db.utils.InterfaceError: connection already closed
ERROR 2025-10-07 06:42:12,589 basehttp 4352 123145531015168 "POST /api/v1/processing/rag/query/ HTTP/1.1" 500 131246
INFO 2025-10-07 07:10:25,467 autoreload 10998 140704670657024 Watching for file changes with StatReloader
INFO 2025-10-07 07:11:13,226 basehttp 10998 123145475391488 "POST /api/v1/processing/rag/query/ HTTP/1.1" 200 420
INFO 2025-10-07 07:12:31,255 basehttp 10998 123145475391488 "POST /api/v1/processing/rag/query/ HTTP/1.1" 200 419
INFO 2025-10-07 07:15:45,122 autoreload 10998 140704670657024 /Users/krohn/PycharmProjects/DME-AGENTS/dgi-extractor/doctrine/services/langchain_rag.py changed, reloading.
INFO 2025-10-07 07:15:46,428 autoreload 12494 140704670657024 Watching for file changes with StatReloader
INFO 2025-10-07 07:18:26,106 autoreload 12494 140704670657024 /Users/krohn/PycharmProjects/DME-AGENTS/dgi-extractor/doctrine/services/langchain_rag.py changed, reloading.
INFO 2025-10-07 07:18:28,333 autoreload 12988 140704670657024 Watching for file changes with StatReloader
INFO 2025-10-07 07:21:07,368 basehttp 12988 123145456967680 "POST /api/v1/processing/rag/query/ HTTP/1.1" 200 309
ERROR 2025-10-07 07:21:13,440 log 12988 123145473757184 Internal Server Error: /api/v1/processing/rag/query/
Traceback (most recent call last):
  File "/Users/krohn/PycharmProjects/DME-AGENTS/dgi-extractor/.venv/lib/python3.12/site-packages/django/db/backends/base/base.py", line 303, in _commit
    return self.connection.commit()
           ^^^^^^^^^^^^^^^^^^^^^^^^
psycopg2.InterfaceError: connection already closed

The above exception was the direct cause of the following exception:

Traceback (most recent call last):
  File "/Users/krohn/PycharmProjects/DME-AGENTS/dgi-extractor/.venv/lib/python3.12/site-packages/django/db/transaction.py", line 263, in __exit__
    connection.commit()
  File "/Users/krohn/PycharmProjects/DME-AGENTS/dgi-extractor/.venv/lib/python3.12/site-packages/django/utils/asyncio.py", line 26, in inner
    return func(*args, **kwargs)
           ^^^^^^^^^^^^^^^^^^^^^
  File "/Users/krohn/PycharmProjects/DME-AGENTS/dgi-extractor/.venv/lib/python3.12/site-packages/django/db/backends/base/base.py", line 327, in commit
    self._commit()
  File "/Users/krohn/PycharmProjects/DME-AGENTS/dgi-extractor/.venv/lib/python3.12/site-packages/django/db/backends/base/base.py", line 302, in _commit
    with debug_transaction(self, "COMMIT"), self.wrap_database_errors:
                                            ^^^^^^^^^^^^^^^^^^^^^^^^^
  File "/Users/krohn/PycharmProjects/DME-AGENTS/dgi-extractor/.venv/lib/python3.12/site-packages/django/db/utils.py", line 91, in __exit__
    raise dj_exc_value.with_traceback(traceback) from exc_value
  File "/Users/krohn/PycharmProjects/DME-AGENTS/dgi-extractor/.venv/lib/python3.12/site-packages/django/db/backends/base/base.py", line 303, in _commit
    return self.connection.commit()
           ^^^^^^^^^^^^^^^^^^^^^^^^
django.db.utils.InterfaceError: connection already closed

During handling of the above exception, another exception occurred:

Traceback (most recent call last):
  File "/Users/krohn/PycharmProjects/DME-AGENTS/dgi-extractor/.venv/lib/python3.12/site-packages/django/db/backends/postgresql/base.py", line 474, in _set_autocommit
    self.connection.autocommit = autocommit
    ^^^^^^^^^^^^^^^^^^^^^^^^^^
psycopg2.InterfaceError: connection already closed

The above exception was the direct cause of the following exception:

Traceback (most recent call last):
  File "/Users/krohn/PycharmProjects/DME-AGENTS/dgi-extractor/.venv/lib/python3.12/site-packages/django/core/handlers/exception.py", line 55, in inner
    response = get_response(request)
               ^^^^^^^^^^^^^^^^^^^^^
  File "/Users/krohn/PycharmProjects/DME-AGENTS/dgi-extractor/.venv/lib/python3.12/site-packages/django/core/handlers/base.py", line 197, in _get_response
    response = wrapped_callback(request, *callback_args, **callback_kwargs)
               ^^^^^^^^^^^^^^^^^^^^^^^^^^^^^^^^^^^^^^^^^^^^^^^^^^^^^^^^^^^^
  File "/Library/Frameworks/Python.framework/Versions/3.12/lib/python3.12/contextlib.py", line 80, in inner
    with self._recreate_cm():
         ^^^^^^^^^^^^^^^^^^^
  File "/Users/krohn/PycharmProjects/DME-AGENTS/dgi-extractor/.venv/lib/python3.12/site-packages/django/db/transaction.py", line 307, in __exit__
    connection.set_autocommit(True)
  File "/Users/krohn/PycharmProjects/DME-AGENTS/dgi-extractor/.venv/lib/python3.12/site-packages/django/db/backends/base/base.py", line 484, in set_autocommit
    self._set_autocommit(autocommit)
  File "/Users/krohn/PycharmProjects/DME-AGENTS/dgi-extractor/.venv/lib/python3.12/site-packages/django/db/backends/postgresql/base.py", line 473, in _set_autocommit
    with self.wrap_database_errors:
         ^^^^^^^^^^^^^^^^^^^^^^^^^
  File "/Users/krohn/PycharmProjects/DME-AGENTS/dgi-extractor/.venv/lib/python3.12/site-packages/django/db/utils.py", line 91, in __exit__
    raise dj_exc_value.with_traceback(traceback) from exc_value
  File "/Users/krohn/PycharmProjects/DME-AGENTS/dgi-extractor/.venv/lib/python3.12/site-packages/django/db/backends/postgresql/base.py", line 474, in _set_autocommit
    self.connection.autocommit = autocommit
    ^^^^^^^^^^^^^^^^^^^^^^^^^^
django.db.utils.InterfaceError: connection already closed
ERROR 2025-10-07 07:21:13,443 basehttp 12988 123145473757184 "POST /api/v1/processing/rag/query/ HTTP/1.1" 500 131246
WARNING 2025-10-07 07:22:09,818 log 12988 123145456967680 Bad Request: /api/v1/processing/rag/query/
WARNING 2025-10-07 07:22:09,819 basehttp 12988 123145456967680 "GET /api/v1/processing/rag/query/ HTTP/1.1" 400 17143
INFO 2025-10-07 07:22:09,922 basehttp 12988 123145456967680 "GET /static/rest_framework/css/bootstrap.min.css HTTP/1.1" 200 121457
INFO 2025-10-07 07:22:09,927 basehttp 12988 123145473757184 "GET /static/rest_framework/css/bootstrap-tweaks.css HTTP/1.1" 200 3426
INFO 2025-10-07 07:22:09,955 basehttp 12988 123145490546688 "GET /static/rest_framework/css/prettify.css HTTP/1.1" 200 817
INFO 2025-10-07 07:22:09,959 basehttp 12988 123145507336192 "GET /static/rest_framework/css/default.css HTTP/1.1" 200 1152
INFO 2025-10-07 07:22:09,991 basehttp 12988 123145490546688 "GET /static/rest_framework/js/ajax-form.js HTTP/1.1" 200 3796
INFO 2025-10-07 07:22:09,994 basehttp 12988 123145473757184 "GET /static/rest_framework/js/jquery-3.7.1.min.js HTTP/1.1" 200 87533
INFO 2025-10-07 07:22:10,000 basehttp 12988 123145507336192 "GET /static/rest_framework/js/csrf.js HTTP/1.1" 200 1793
INFO 2025-10-07 07:22:10,005 basehttp 12988 123145456967680 "GET /static/rest_framework/js/default.js HTTP/1.1" 200 1268
INFO 2025-10-07 07:22:10,005 basehttp 12988 123145490546688 "GET /static/rest_framework/js/load-ajax-form.js HTTP/1.1" 200 59
INFO 2025-10-07 07:22:10,013 basehttp 12988 123145540915200 "GET /static/rest_framework/js/prettify-min.js HTTP/1.1" 200 13632
INFO 2025-10-07 07:22:10,014 basehttp 12988 123145524125696 "GET /static/rest_framework/js/bootstrap.min.js HTTP/1.1" 200 39680
INFO 2025-10-07 07:22:10,067 basehttp 12988 123145456967680 "GET /static/rest_framework/img/grid.png HTTP/1.1" 200 1458
WARNING 2025-10-07 07:22:10,507 log 12988 123145456967680 Not Found: /favicon.ico
WARNING 2025-10-07 07:22:10,507 basehttp 12988 123145456967680 "GET /favicon.ico HTTP/1.1" 404 6188
ERROR 2025-10-07 07:23:48,519 log 12988 123145456967680 Internal Server Error: /api/v1/processing/rag/query/
Traceback (most recent call last):
  File "/Users/krohn/PycharmProjects/DME-AGENTS/dgi-extractor/.venv/lib/python3.12/site-packages/django/core/handlers/exception.py", line 55, in inner
    response = get_response(request)
               ^^^^^^^^^^^^^^^^^^^^^
  File "/Users/krohn/PycharmProjects/DME-AGENTS/dgi-extractor/.venv/lib/python3.12/site-packages/django/core/handlers/base.py", line 220, in _get_response
    response = response.render()
               ^^^^^^^^^^^^^^^^^
  File "/Users/krohn/PycharmProjects/DME-AGENTS/dgi-extractor/.venv/lib/python3.12/site-packages/django/template/response.py", line 114, in render
    self.content = self.rendered_content
                   ^^^^^^^^^^^^^^^^^^^^^
  File "/Users/krohn/PycharmProjects/DME-AGENTS/dgi-extractor/.venv/lib/python3.12/site-packages/rest_framework/response.py", line 74, in rendered_content
    ret = renderer.render(self.data, accepted_media_type, context)
          ^^^^^^^^^^^^^^^^^^^^^^^^^^^^^^^^^^^^^^^^^^^^^^^^^^^^^^^^
  File "/Users/krohn/PycharmProjects/DME-AGENTS/dgi-extractor/.venv/lib/python3.12/site-packages/rest_framework/renderers.py", line 731, in render
    context = self.get_context(data, accepted_media_type, renderer_context)
              ^^^^^^^^^^^^^^^^^^^^^^^^^^^^^^^^^^^^^^^^^^^^^^^^^^^^^^^^^^^^^
  File "/Users/krohn/PycharmProjects/DME-AGENTS/dgi-extractor/.venv/lib/python3.12/site-packages/rest_framework/renderers.py", line 709, in get_context
    'filter_form': self.get_filter_form(data, view, request),
                   ^^^^^^^^^^^^^^^^^^^^^^^^^^^^^^^^^^^^^^^^^
  File "/Users/krohn/PycharmProjects/DME-AGENTS/dgi-extractor/.venv/lib/python3.12/site-packages/rest_framework/renderers.py", line 637, in get_filter_form
    queryset = view.get_queryset()
               ^^^^^^^^^^^^^^^^^^^
  File "/Users/krohn/PycharmProjects/DME-AGENTS/dgi-extractor/.venv/lib/python3.12/site-packages/rest_framework/generics.py", line 67, in get_queryset
    assert self.queryset is not None, (
           ^^^^^^^^^^^^^^^^^^^^^^^^^
AssertionError: 'RAGQueryView' should either include a `queryset` attribute, or override the `get_queryset()` method.
ERROR 2025-10-07 07:23:48,522 basehttp 12988 123145456967680 "POST /api/v1/processing/rag/query/ HTTP/1.1" 500 107139
WARNING 2025-10-07 07:24:25,508 log 12988 123145473757184 Bad Request: /api/v1/processing/rag/query/
INFO 2025-10-07 07:24:25,509 basehttp 12988 123145473757184 - Broken pipe from ('127.0.0.1', 64757)
INFO 2025-10-07 07:24:56,535 autoreload 12988 140704670657024 /Users/krohn/PycharmProjects/DME-AGENTS/dgi-extractor/doctrine/views_1.py changed, reloading.
INFO 2025-10-07 07:24:57,952 autoreload 14309 140704670657024 Watching for file changes with StatReloader
INFO 2025-10-07 07:25:19,370 autoreload 14309 140704670657024 /Users/krohn/PycharmProjects/DME-AGENTS/dgi-extractor/doctrine/views_1.py changed, reloading.
INFO 2025-10-07 07:25:20,202 autoreload 14388 140704670657024 Watching for file changes with StatReloader
INFO 2025-10-07 07:27:29,560 autoreload 14657 140704670657024 Watching for file changes with StatReloader
INFO 2025-10-07 07:28:39,326 autoreload 14657 140704670657024 /Users/krohn/PycharmProjects/DME-AGENTS/dgi-extractor/doctrine/views_1.py changed, reloading.
INFO 2025-10-07 07:28:40,506 autoreload 14846 140704670657024 Watching for file changes with StatReloader
INFO 2025-10-07 07:29:52,278 basehttp 14846 123145522413568 "POST /api/v1/processing/rag/query/ HTTP/1.1" 200 309
WARNING 2025-10-07 07:29:53,070 log 14846 123145539203072 Bad Request: /api/v1/processing/rag/query/
WARNING 2025-10-07 07:29:53,070 basehttp 14846 123145539203072 "GET /api/v1/processing/rag/query/ HTTP/1.1" 400 11993
WARNING 2025-10-07 07:30:44,021 log 14846 123145539203072 Bad Request: /api/v1/processing/rag/query/
WARNING 2025-10-07 07:30:44,022 basehttp 14846 123145539203072 "POST /api/v1/processing/rag/query/ HTTP/1.1" 400 12014
INFO 2025-10-07 07:32:42,578 basehttp 14846 123145522413568 "POST /api/v1/processing/rag/query/ HTTP/1.1" 200 307
INFO 2025-10-07 07:34:33,167 autoreload 14846 140704670657024 /Users/krohn/PycharmProjects/DME-AGENTS/dgi-extractor/doctrine/services/langchain_rag.py changed, reloading.
INFO 2025-10-07 07:34:34,526 autoreload 15528 140704670657024 Watching for file changes with StatReloader
INFO 2025-10-07 07:35:57,832 basehttp 15528 123145371955200 "POST /api/v1/processing/rag/query/ HTTP/1.1" 200 300
ERROR 2025-10-07 07:37:00,693 log 15528 123145371955200 Service Unavailable: /api/v1/processing/rag/query/
ERROR 2025-10-07 07:37:00,694 basehttp 15528 123145371955200 "POST /api/v1/processing/rag/query/ HTTP/1.1" 503 184
INFO 2025-10-07 07:39:38,702 autoreload 15528 140704670657024 /Users/krohn/PycharmProjects/DME-AGENTS/dgi-extractor/doctrine/services/rag.py changed, reloading.
INFO 2025-10-07 07:39:40,177 autoreload 16786 140704670657024 Watching for file changes with StatReloader
INFO 2025-10-07 07:40:21,909 basehttp 16786 123145465876480 "POST /api/v1/processing/rag/query/ HTTP/1.1" 200 400
INFO 2025-10-07 07:41:12,041 basehttp 16786 123145465876480 "POST /api/v1/processing/rag/query/ HTTP/1.1" 200 400
INFO 2025-10-07 07:41:59,598 basehttp 16786 123145465876480 "GET /api/v1/processing/rag/models/info/ HTTP/1.1" 200 221
INFO 2025-10-07 07:43:55,732 basehttp 16786 123145465876480 "POST /api/v1/processing/rag/query/ HTTP/1.1" 200 400
INFO 2025-10-07 07:52:16,406 autoreload 16786 140704670657024 /Users/krohn/PycharmProjects/DME-AGENTS/dgi-extractor/doctrine/services/rag.py changed, reloading.
INFO 2025-10-07 07:52:19,972 autoreload 19140 140704670657024 Watching for file changes with StatReloader
INFO 2025-10-07 08:02:29,861 basehttp 19140 123145391308800 "POST /api/v1/processing/rag/query/ HTTP/1.1" 200 482
INFO 2025-10-07 08:08:13,665 autoreload 19140 140704670657024 /Users/krohn/PycharmProjects/DME-AGENTS/dgi-extractor/doctrine/views_1.py changed, reloading.
INFO 2025-10-07 08:08:15,522 autoreload 20585 140704670657024 Watching for file changes with StatReloader
INFO 2025-10-07 08:10:59,622 autoreload 20585 140704670657024 /Users/krohn/PycharmProjects/DME-AGENTS/dgi-extractor/doctrine/views_1.py changed, reloading.
INFO 2025-10-07 08:11:02,495 autoreload 20801 140704670657024 Watching for file changes with StatReloader
INFO 2025-10-07 08:13:24,213 autoreload 20801 140704670657024 /Users/krohn/PycharmProjects/DME-AGENTS/dgi-extractor/doctrine/views_1.py changed, reloading.
INFO 2025-10-07 08:13:26,958 autoreload 20999 140704670657024 Watching for file changes with StatReloader
INFO 2025-10-07 08:14:36,954 autoreload 20999 140704670657024 /Users/krohn/PycharmProjects/DME-AGENTS/dgi-extractor/doctrine/views_1.py changed, reloading.
INFO 2025-10-07 08:14:38,351 autoreload 21117 140704670657024 Watching for file changes with StatReloader
INFO 2025-10-07 08:15:21,195 autoreload 21186 140704670657024 Watching for file changes with StatReloader
ERROR 2025-10-07 08:16:07,692 log 21186 123145532342272 Service Unavailable: /api/v1/processing/rag/query/
ERROR 2025-10-07 08:16:07,693 basehttp 21186 123145532342272 "POST /api/v1/processing/rag/query/ HTTP/1.1" 503 334
INFO 2025-10-07 08:19:33,387 autoreload 21186 140704670657024 /Users/krohn/PycharmProjects/DME-AGENTS/dgi-extractor/doctrine/services/rag_service.py changed, reloading.
INFO 2025-10-07 08:19:37,427 autoreload 21603 140704670657024 Watching for file changes with StatReloader
INFO 2025-10-07 08:22:09,195 autoreload 21837 140704670657024 Watching for file changes with StatReloader
INFO 2025-10-07 08:27:34,182 autoreload 22259 140704670657024 Watching for file changes with StatReloader
INFO 2025-10-07 08:27:58,504 autoreload 22259 140704670657024 /Users/krohn/PycharmProjects/DME-AGENTS/dgi-extractor/doctrine/serializers.py changed, reloading.
INFO 2025-10-07 08:27:59,682 autoreload 22310 140704670657024 Watching for file changes with StatReloader
INFO 2025-10-07 08:28:08,954 autoreload 22310 140704670657024 /Users/krohn/PycharmProjects/DME-AGENTS/dgi-extractor/doctrine/serializers.py changed, reloading.
INFO 2025-10-07 08:28:10,285 autoreload 22342 140704670657024 Watching for file changes with StatReloader
INFO 2025-10-07 10:20:39,955 autoreload 22342 140704670657024 /Users/krohn/PycharmProjects/DME-AGENTS/dgi-extractor/doctrine/serializers.py changed, reloading.
INFO 2025-10-07 10:20:41,427 autoreload 32051 140704670657024 Watching for file changes with StatReloader
ERROR 2025-10-07 10:21:41,649 log 32051 123145373954048 Internal Server Error: /api/v1/processing/rag/query/
Traceback (most recent call last):
  File "/Users/krohn/PycharmProjects/DME-AGENTS/dgi-extractor/.venv/lib/python3.12/site-packages/django/core/handlers/exception.py", line 55, in inner
    response = get_response(request)
               ^^^^^^^^^^^^^^^^^^^^^
  File "/Users/krohn/PycharmProjects/DME-AGENTS/dgi-extractor/.venv/lib/python3.12/site-packages/django/core/handlers/base.py", line 197, in _get_response
    response = wrapped_callback(request, *callback_args, **callback_kwargs)
               ^^^^^^^^^^^^^^^^^^^^^^^^^^^^^^^^^^^^^^^^^^^^^^^^^^^^^^^^^^^^
  File "/Library/Frameworks/Python.framework/Versions/3.12/lib/python3.12/contextlib.py", line 81, in inner
    return func(*args, **kwds)
           ^^^^^^^^^^^^^^^^^^^
  File "/Users/krohn/PycharmProjects/DME-AGENTS/dgi-extractor/.venv/lib/python3.12/site-packages/django/views/decorators/csrf.py", line 65, in _view_wrapper
    return view_func(request, *args, **kwargs)
           ^^^^^^^^^^^^^^^^^^^^^^^^^^^^^^^^^^^
  File "/Users/krohn/PycharmProjects/DME-AGENTS/dgi-extractor/.venv/lib/python3.12/site-packages/django/views/generic/base.py", line 98, in view
    self = cls(**initkwargs)
           ^^^^^^^^^^^^^^^^^
  File "/Users/krohn/PycharmProjects/DME-AGENTS/dgi-extractor/doctrine/views_1.py", line 1470, in __init__
    self.rag_service = PDFRAGService(pdf_path=PDF_PATH)
                       ^^^^^^^^^^^^^^^^^^^^^^^^^^^^^^^^
TypeError: PDFRAGService.__init__() got an unexpected keyword argument 'pdf_path'
ERROR 2025-10-07 10:21:41,651 basehttp 32051 123145373954048 "POST /api/v1/processing/rag/query/ HTTP/1.1" 500 88519
INFO 2025-10-07 10:23:34,901 autoreload 32051 140704670657024 /Users/krohn/PycharmProjects/DME-AGENTS/dgi-extractor/doctrine/views_1.py changed, reloading.
INFO 2025-10-07 10:23:36,676 autoreload 32529 140704670657024 Watching for file changes with StatReloader
INFO 2025-10-07 10:24:50,288 basehttp 32529 123145432383488 "POST /api/v1/processing/rag/query/ HTTP/1.1" 200 460
INFO 2025-10-07 10:26:16,577 basehttp 32529 123145432383488 "POST /api/v1/processing/rag/query/ HTTP/1.1" 200 435
INFO 2025-10-07 10:28:28,517 autoreload 32529 140704670657024 /Users/krohn/PycharmProjects/DME-AGENTS/dgi-extractor/doctrine/views_1.py changed, reloading.
INFO 2025-10-07 10:28:30,665 autoreload 33192 140704670657024 Watching for file changes with StatReloader
INFO 2025-10-07 10:29:19,506 autoreload 33192 140704670657024 /Users/krohn/PycharmProjects/DME-AGENTS/dgi-extractor/doctrine/services/rag_service.py changed, reloading.
INFO 2025-10-07 10:29:20,784 autoreload 33408 140704670657024 Watching for file changes with StatReloader
INFO 2025-10-07 10:29:48,310 autoreload 33408 140704670657024 /Users/krohn/PycharmProjects/DME-AGENTS/dgi-extractor/doctrine/services/rag_service.py changed, reloading.
INFO 2025-10-07 10:29:49,627 autoreload 33475 140704670657024 Watching for file changes with StatReloader
INFO 2025-10-07 10:30:04,251 autoreload 33475 140704670657024 /Users/krohn/PycharmProjects/DME-AGENTS/dgi-extractor/doctrine/services/rag_service.py changed, reloading.
INFO 2025-10-07 10:30:05,584 autoreload 33541 140704670657024 Watching for file changes with StatReloader
INFO 2025-10-07 10:30:29,401 autoreload 33541 140704670657024 /Users/krohn/PycharmProjects/DME-AGENTS/dgi-extractor/doctrine/services/rag_service.py changed, reloading.
INFO 2025-10-07 10:30:30,716 autoreload 33598 140704670657024 Watching for file changes with StatReloader
INFO 2025-10-07 10:32:32,738 basehttp 33598 123145553473536 "POST /api/v1/processing/rag/query/ HTTP/1.1" 200 435
INFO 2025-10-07 10:35:03,125 basehttp 33598 123145553473536 "POST /api/v1/processing/rag/query/ HTTP/1.1" 200 3688
INFO 2025-10-07 10:37:39,962 basehttp 33598 123145553473536 "OPTIONS /api/v1/public/all-extracted-content?page=1&page_size=10 HTTP/1.1" 200 0
INFO 2025-10-07 10:37:40,251 basehttp 33598 123145553473536 "OPTIONS /api/v1/public/all-extracted-content/?page=1&page_size=10 HTTP/1.1" 200 0
INFO 2025-10-07 10:37:40,268 basehttp 33598 123145570263040 "OPTIONS /api/v1/public/all-extracted-content/?page=1&page_size=10 HTTP/1.1" 200 0
INFO 2025-10-07 10:37:40,318 basehttp 33598 123145587052544 "OPTIONS /api/v1/public/all-extracted-content/?page=1&page_size=10 HTTP/1.1" 200 0
INFO 2025-10-07 10:38:56,034 basehttp 33598 123145553473536 "GET /api/v1/public/all-extracted-content/?page=1&page_size=10 HTTP/1.1" 200 20790
INFO 2025-10-07 10:39:16,814 basehttp 33598 123145587052544 "GET /api/v1/public/all-extracted-content/?page=1&page_size=10 HTTP/1.1" 200 20790
INFO 2025-10-07 10:39:18,271 basehttp 33598 123145570263040 "GET /api/v1/public/all-extracted-content/?page=1&page_size=10 HTTP/1.1" 200 20790
INFO 2025-10-07 10:41:02,706 autoreload 33598 140704670657024 /Users/krohn/PycharmProjects/DME-AGENTS/dgi-extractor/doctrine/services/rag_service.py changed, reloading.
INFO 2025-10-07 10:41:04,933 autoreload 35260 140704670657024 Watching for file changes with StatReloader
INFO 2025-10-07 10:41:34,293 autoreload 35260 140704670657024 /Users/krohn/PycharmProjects/DME-AGENTS/dgi-extractor/doctrine/services/rag_service.py changed, reloading.
INFO 2025-10-07 10:41:36,046 autoreload 35376 140704670657024 Watching for file changes with StatReloader
INFO 2025-10-07 10:41:52,881 autoreload 35376 140704670657024 /Users/krohn/PycharmProjects/DME-AGENTS/dgi-extractor/doctrine/services/rag_service.py changed, reloading.
INFO 2025-10-07 10:41:54,568 autoreload 35447 140704670657024 Watching for file changes with StatReloader
INFO 2025-10-07 10:44:20,108 basehttp 35447 123145525866496 "POST /api/v1/processing/rag/query/ HTTP/1.1" 200 3688
INFO 2025-10-07 10:45:46,364 autoreload 35447 140704670657024 /Users/krohn/PycharmProjects/DME-AGENTS/dgi-extractor/doctrine/services/rag_service.py changed, reloading.
INFO 2025-10-07 10:45:48,147 autoreload 36032 140704670657024 Watching for file changes with StatReloader
INFO 2025-10-07 10:46:04,729 autoreload 36032 140704670657024 /Users/krohn/PycharmProjects/DME-AGENTS/dgi-extractor/doctrine/services/rag_service.py changed, reloading.
INFO 2025-10-07 10:46:06,396 autoreload 36108 140704670657024 Watching for file changes with StatReloader
INFO 2025-10-07 10:46:21,938 autoreload 36108 140704670657024 /Users/krohn/PycharmProjects/DME-AGENTS/dgi-extractor/doctrine/services/rag_service.py changed, reloading.
INFO 2025-10-07 10:46:23,589 autoreload 36161 140704670657024 Watching for file changes with StatReloader
INFO 2025-10-07 10:46:38,504 autoreload 36161 140704670657024 /Users/krohn/PycharmProjects/DME-AGENTS/dgi-extractor/doctrine/services/rag_service.py changed, reloading.
INFO 2025-10-07 10:46:40,377 autoreload 36214 140704670657024 Watching for file changes with StatReloader
INFO 2025-10-07 10:47:25,634 autoreload 36214 140704670657024 /Users/krohn/PycharmProjects/DME-AGENTS/dgi-extractor/doctrine/services/rag_service.py changed, reloading.
INFO 2025-10-07 10:47:26,887 autoreload 36337 140704670657024 Watching for file changes with StatReloader
ERROR 2025-10-07 10:50:06,862 log 36337 123145420644352 Service Unavailable: /api/v1/processing/rag/query/
ERROR 2025-10-07 10:50:06,863 basehttp 36337 123145420644352 "POST /api/v1/processing/rag/query/ HTTP/1.1" 503 310
INFO 2025-10-07 10:50:42,311 autoreload 36740 140704670657024 Watching for file changes with StatReloader
INFO 2025-10-07 10:56:17,839 autoreload 36740 140704670657024 /Users/krohn/PycharmProjects/DME-AGENTS/dgi-extractor/.venv/lib/python3.12/site-packages/numpy/dtypes.py changed, reloading.
INFO 2025-10-07 10:56:19,848 autoreload 39464 140704670657024 Watching for file changes with StatReloader
INFO 2025-10-07 10:57:14,587 autoreload 39876 140704670657024 Watching for file changes with StatReloader
INFO 2025-10-07 11:00:08,217 basehttp 39876 123145514237952 "POST /api/v1/processing/rag/query/ HTTP/1.1" 200 3932
INFO 2025-10-07 11:05:12,314 autoreload 39876 140704670657024 /Users/krohn/PycharmProjects/DME-AGENTS/dgi-extractor/core/settings.py changed, reloading.
INFO 2025-10-07 11:05:15,123 autoreload 40520 140704670657024 Watching for file changes with StatReloader
INFO 2025-10-07 11:06:51,710 basehttp 40520 123145441443840 "POST /api/v1/processing/rag/query/ HTTP/1.1" 200 3932
INFO 2025-10-07 11:08:53,096 autoreload 40520 140704670657024 /Users/krohn/PycharmProjects/DME-AGENTS/dgi-extractor/core/settings.py changed, reloading.
INFO 2025-10-07 11:08:55,446 autoreload 40850 140704670657024 Watching for file changes with StatReloader
INFO 2025-10-07 11:11:06,447 basehttp 40850 123145361686528 "POST /api/v1/processing/rag/query/ HTTP/1.1" 200 3932
INFO 2025-10-07 11:14:13,966 autoreload 40850 140704670657024 /Users/krohn/PycharmProjects/DME-AGENTS/dgi-extractor/doctrine/services/rag_service.py changed, reloading.
INFO 2025-10-07 11:14:16,558 autoreload 41808 140704670657024 Watching for file changes with StatReloader
INFO 2025-10-07 11:15:33,021 autoreload 42024 140704670657024 Watching for file changes with StatReloader
INFO 2025-10-07 11:17:50,652 basehttp 42024 123145362857984 "POST /api/v1/processing/rag/query/ HTTP/1.1" 200 4017
INFO 2025-10-07 11:21:00,511 basehttp 42024 123145362857984 "POST /api/v1/processing/rag/query/ HTTP/1.1" 200 4238
WARNING 2025-10-07 11:23:48,426 log 42024 123145362857984 Bad Request: /api/v1/processing/rag/query/
WARNING 2025-10-07 11:23:48,430 basehttp 42024 123145362857984 "POST /api/v1/processing/rag/query/ HTTP/1.1" 400 37
INFO 2025-10-07 11:24:37,850 basehttp 42024 123145379647488 - Broken pipe from ('127.0.0.1', 52455)
INFO 2025-10-07 11:46:16,309 basehttp 42024 123145362857984 "GET /api/v1/public/all-extracted-content/?page=1&page_size=10 HTTP/1.1" 200 20790
INFO 2025-10-07 11:46:30,163 basehttp 42024 123145379647488 "GET /api/v1/public/all-extracted-content/?page=1&page_size=10 HTTP/1.1" 200 20790
ERROR 2025-10-07 11:46:41,790 log 42024 123145396436992 Internal Server Error: /api/v1/public/all-extracted-content/
Traceback (most recent call last):
  File "/Users/krohn/PycharmProjects/DME-AGENTS/dgi-extractor/.venv/lib/python3.12/site-packages/django/db/backends/base/base.py", line 303, in _commit
    return self.connection.commit()
           ^^^^^^^^^^^^^^^^^^^^^^^^
psycopg2.OperationalError: server closed the connection unexpectedly
	This probably means the server terminated abnormally
	before or while processing the request.


The above exception was the direct cause of the following exception:

Traceback (most recent call last):
  File "/Users/krohn/PycharmProjects/DME-AGENTS/dgi-extractor/.venv/lib/python3.12/site-packages/django/core/handlers/exception.py", line 55, in inner
    response = get_response(request)
               ^^^^^^^^^^^^^^^^^^^^^
  File "/Users/krohn/PycharmProjects/DME-AGENTS/dgi-extractor/.venv/lib/python3.12/site-packages/django/core/handlers/base.py", line 197, in _get_response
    response = wrapped_callback(request, *callback_args, **callback_kwargs)
               ^^^^^^^^^^^^^^^^^^^^^^^^^^^^^^^^^^^^^^^^^^^^^^^^^^^^^^^^^^^^
  File "/Library/Frameworks/Python.framework/Versions/3.12/lib/python3.12/contextlib.py", line 80, in inner
    with self._recreate_cm():
         ^^^^^^^^^^^^^^^^^^^
  File "/Users/krohn/PycharmProjects/DME-AGENTS/dgi-extractor/.venv/lib/python3.12/site-packages/django/db/transaction.py", line 263, in __exit__
    connection.commit()
  File "/Users/krohn/PycharmProjects/DME-AGENTS/dgi-extractor/.venv/lib/python3.12/site-packages/django/utils/asyncio.py", line 26, in inner
    return func(*args, **kwargs)
           ^^^^^^^^^^^^^^^^^^^^^
  File "/Users/krohn/PycharmProjects/DME-AGENTS/dgi-extractor/.venv/lib/python3.12/site-packages/django/db/backends/base/base.py", line 327, in commit
    self._commit()
  File "/Users/krohn/PycharmProjects/DME-AGENTS/dgi-extractor/.venv/lib/python3.12/site-packages/django/db/backends/base/base.py", line 302, in _commit
    with debug_transaction(self, "COMMIT"), self.wrap_database_errors:
                                            ^^^^^^^^^^^^^^^^^^^^^^^^^
  File "/Users/krohn/PycharmProjects/DME-AGENTS/dgi-extractor/.venv/lib/python3.12/site-packages/django/db/utils.py", line 91, in __exit__
    raise dj_exc_value.with_traceback(traceback) from exc_value
  File "/Users/krohn/PycharmProjects/DME-AGENTS/dgi-extractor/.venv/lib/python3.12/site-packages/django/db/backends/base/base.py", line 303, in _commit
    return self.connection.commit()
           ^^^^^^^^^^^^^^^^^^^^^^^^
django.db.utils.OperationalError: server closed the connection unexpectedly
	This probably means the server terminated abnormally
	before or while processing the request.

ERROR 2025-10-07 11:46:43,011 basehttp 42024 123145396436992 "GET /api/v1/public/all-extracted-content/?page=1&page_size=10 HTTP/1.1" 500 108487
INFO 2025-10-07 11:54:28,542 basehttp 42024 123145362857984 "OPTIONS /api/v1/public/all-extracted-content?page=1&page_size=10 HTTP/1.1" 200 0
INFO 2025-10-07 11:54:28,662 basehttp 42024 123145362857984 "GET /api/v1/public/all-extracted-content?page=1&page_size=10 HTTP/1.1" 301 0
INFO 2025-10-07 11:54:28,787 basehttp 42024 123145362857984 "OPTIONS /api/v1/public/all-extracted-content/?page=1&page_size=10 HTTP/1.1" 200 0
ERROR 2025-10-07 11:54:29,036 log 42024 123145362857984 Internal Server Error: /api/v1/public/all-extracted-content/
Traceback (most recent call last):
  File "/Users/krohn/PycharmProjects/DME-AGENTS/dgi-extractor/.venv/lib/python3.12/site-packages/django/db/backends/base/base.py", line 279, in ensure_connection
    self.connect()
  File "/Users/krohn/PycharmProjects/DME-AGENTS/dgi-extractor/.venv/lib/python3.12/site-packages/django/utils/asyncio.py", line 26, in inner
    return func(*args, **kwargs)
           ^^^^^^^^^^^^^^^^^^^^^
  File "/Users/krohn/PycharmProjects/DME-AGENTS/dgi-extractor/.venv/lib/python3.12/site-packages/django/db/backends/base/base.py", line 256, in connect
    self.connection = self.get_new_connection(conn_params)
                      ^^^^^^^^^^^^^^^^^^^^^^^^^^^^^^^^^^^^
  File "/Users/krohn/PycharmProjects/DME-AGENTS/dgi-extractor/.venv/lib/python3.12/site-packages/django/utils/asyncio.py", line 26, in inner
    return func(*args, **kwargs)
           ^^^^^^^^^^^^^^^^^^^^^
  File "/Users/krohn/PycharmProjects/DME-AGENTS/dgi-extractor/.venv/lib/python3.12/site-packages/django/db/backends/postgresql/base.py", line 332, in get_new_connection
    connection = self.Database.connect(**conn_params)
                 ^^^^^^^^^^^^^^^^^^^^^^^^^^^^^^^^^^^^
  File "/Users/krohn/PycharmProjects/DME-AGENTS/dgi-extractor/.venv/lib/python3.12/site-packages/psycopg2/__init__.py", line 122, in connect
    conn = _connect(dsn, connection_factory=connection_factory, **kwasync)
           ^^^^^^^^^^^^^^^^^^^^^^^^^^^^^^^^^^^^^^^^^^^^^^^^^^^^^^^^^^^^^^^
psycopg2.OperationalError: connection to server at "37.60.239.221", port 5433 failed: Network is unreachable
	Is the server running on that host and accepting TCP/IP connections?


The above exception was the direct cause of the following exception:

Traceback (most recent call last):
  File "/Users/krohn/PycharmProjects/DME-AGENTS/dgi-extractor/.venv/lib/python3.12/site-packages/django/core/handlers/exception.py", line 55, in inner
    response = get_response(request)
               ^^^^^^^^^^^^^^^^^^^^^
  File "/Users/krohn/PycharmProjects/DME-AGENTS/dgi-extractor/.venv/lib/python3.12/site-packages/django/core/handlers/base.py", line 197, in _get_response
    response = wrapped_callback(request, *callback_args, **callback_kwargs)
               ^^^^^^^^^^^^^^^^^^^^^^^^^^^^^^^^^^^^^^^^^^^^^^^^^^^^^^^^^^^^
  File "/Library/Frameworks/Python.framework/Versions/3.12/lib/python3.12/contextlib.py", line 80, in inner
    with self._recreate_cm():
         ^^^^^^^^^^^^^^^^^^^
  File "/Users/krohn/PycharmProjects/DME-AGENTS/dgi-extractor/.venv/lib/python3.12/site-packages/django/db/transaction.py", line 198, in __enter__
    if not connection.get_autocommit():
           ^^^^^^^^^^^^^^^^^^^^^^^^^^^
  File "/Users/krohn/PycharmProjects/DME-AGENTS/dgi-extractor/.venv/lib/python3.12/site-packages/django/db/backends/base/base.py", line 454, in get_autocommit
    self.ensure_connection()
  File "/Users/krohn/PycharmProjects/DME-AGENTS/dgi-extractor/.venv/lib/python3.12/site-packages/django/utils/asyncio.py", line 26, in inner
    return func(*args, **kwargs)
           ^^^^^^^^^^^^^^^^^^^^^
  File "/Users/krohn/PycharmProjects/DME-AGENTS/dgi-extractor/.venv/lib/python3.12/site-packages/django/db/backends/base/base.py", line 278, in ensure_connection
    with self.wrap_database_errors:
         ^^^^^^^^^^^^^^^^^^^^^^^^^
  File "/Users/krohn/PycharmProjects/DME-AGENTS/dgi-extractor/.venv/lib/python3.12/site-packages/django/db/utils.py", line 91, in __exit__
    raise dj_exc_value.with_traceback(traceback) from exc_value
  File "/Users/krohn/PycharmProjects/DME-AGENTS/dgi-extractor/.venv/lib/python3.12/site-packages/django/db/backends/base/base.py", line 279, in ensure_connection
    self.connect()
  File "/Users/krohn/PycharmProjects/DME-AGENTS/dgi-extractor/.venv/lib/python3.12/site-packages/django/utils/asyncio.py", line 26, in inner
    return func(*args, **kwargs)
           ^^^^^^^^^^^^^^^^^^^^^
  File "/Users/krohn/PycharmProjects/DME-AGENTS/dgi-extractor/.venv/lib/python3.12/site-packages/django/db/backends/base/base.py", line 256, in connect
    self.connection = self.get_new_connection(conn_params)
                      ^^^^^^^^^^^^^^^^^^^^^^^^^^^^^^^^^^^^
  File "/Users/krohn/PycharmProjects/DME-AGENTS/dgi-extractor/.venv/lib/python3.12/site-packages/django/utils/asyncio.py", line 26, in inner
    return func(*args, **kwargs)
           ^^^^^^^^^^^^^^^^^^^^^
  File "/Users/krohn/PycharmProjects/DME-AGENTS/dgi-extractor/.venv/lib/python3.12/site-packages/django/db/backends/postgresql/base.py", line 332, in get_new_connection
    connection = self.Database.connect(**conn_params)
                 ^^^^^^^^^^^^^^^^^^^^^^^^^^^^^^^^^^^^
  File "/Users/krohn/PycharmProjects/DME-AGENTS/dgi-extractor/.venv/lib/python3.12/site-packages/psycopg2/__init__.py", line 122, in connect
    conn = _connect(dsn, connection_factory=connection_factory, **kwasync)
           ^^^^^^^^^^^^^^^^^^^^^^^^^^^^^^^^^^^^^^^^^^^^^^^^^^^^^^^^^^^^^^^
django.db.utils.OperationalError: connection to server at "37.60.239.221", port 5433 failed: Network is unreachable
	Is the server running on that host and accepting TCP/IP connections?

ERROR 2025-10-07 11:54:29,058 basehttp 42024 123145362857984 "GET /api/v1/public/all-extracted-content/?page=1&page_size=10 HTTP/1.1" 500 153582
INFO 2025-10-07 11:54:37,593 basehttp 42024 123145362857984 "OPTIONS /api/v1/processing/rag/query/ HTTP/1.1" 200 0
ERROR 2025-10-07 11:54:37,701 log 42024 123145362857984 Internal Server Error: /api/v1/processing/rag/query/
Traceback (most recent call last):
  File "/Users/krohn/PycharmProjects/DME-AGENTS/dgi-extractor/.venv/lib/python3.12/site-packages/django/db/backends/base/base.py", line 279, in ensure_connection
    self.connect()
  File "/Users/krohn/PycharmProjects/DME-AGENTS/dgi-extractor/.venv/lib/python3.12/site-packages/django/utils/asyncio.py", line 26, in inner
    return func(*args, **kwargs)
           ^^^^^^^^^^^^^^^^^^^^^
  File "/Users/krohn/PycharmProjects/DME-AGENTS/dgi-extractor/.venv/lib/python3.12/site-packages/django/db/backends/base/base.py", line 256, in connect
    self.connection = self.get_new_connection(conn_params)
                      ^^^^^^^^^^^^^^^^^^^^^^^^^^^^^^^^^^^^
  File "/Users/krohn/PycharmProjects/DME-AGENTS/dgi-extractor/.venv/lib/python3.12/site-packages/django/utils/asyncio.py", line 26, in inner
    return func(*args, **kwargs)
           ^^^^^^^^^^^^^^^^^^^^^
  File "/Users/krohn/PycharmProjects/DME-AGENTS/dgi-extractor/.venv/lib/python3.12/site-packages/django/db/backends/postgresql/base.py", line 332, in get_new_connection
    connection = self.Database.connect(**conn_params)
                 ^^^^^^^^^^^^^^^^^^^^^^^^^^^^^^^^^^^^
  File "/Users/krohn/PycharmProjects/DME-AGENTS/dgi-extractor/.venv/lib/python3.12/site-packages/psycopg2/__init__.py", line 122, in connect
    conn = _connect(dsn, connection_factory=connection_factory, **kwasync)
           ^^^^^^^^^^^^^^^^^^^^^^^^^^^^^^^^^^^^^^^^^^^^^^^^^^^^^^^^^^^^^^^
psycopg2.OperationalError: connection to server at "37.60.239.221", port 5433 failed: Network is unreachable
	Is the server running on that host and accepting TCP/IP connections?


The above exception was the direct cause of the following exception:

Traceback (most recent call last):
  File "/Users/krohn/PycharmProjects/DME-AGENTS/dgi-extractor/.venv/lib/python3.12/site-packages/django/core/handlers/exception.py", line 55, in inner
    response = get_response(request)
               ^^^^^^^^^^^^^^^^^^^^^
  File "/Users/krohn/PycharmProjects/DME-AGENTS/dgi-extractor/.venv/lib/python3.12/site-packages/django/core/handlers/base.py", line 197, in _get_response
    response = wrapped_callback(request, *callback_args, **callback_kwargs)
               ^^^^^^^^^^^^^^^^^^^^^^^^^^^^^^^^^^^^^^^^^^^^^^^^^^^^^^^^^^^^
  File "/Library/Frameworks/Python.framework/Versions/3.12/lib/python3.12/contextlib.py", line 80, in inner
    with self._recreate_cm():
         ^^^^^^^^^^^^^^^^^^^
  File "/Users/krohn/PycharmProjects/DME-AGENTS/dgi-extractor/.venv/lib/python3.12/site-packages/django/db/transaction.py", line 198, in __enter__
    if not connection.get_autocommit():
           ^^^^^^^^^^^^^^^^^^^^^^^^^^^
  File "/Users/krohn/PycharmProjects/DME-AGENTS/dgi-extractor/.venv/lib/python3.12/site-packages/django/db/backends/base/base.py", line 454, in get_autocommit
    self.ensure_connection()
  File "/Users/krohn/PycharmProjects/DME-AGENTS/dgi-extractor/.venv/lib/python3.12/site-packages/django/utils/asyncio.py", line 26, in inner
    return func(*args, **kwargs)
           ^^^^^^^^^^^^^^^^^^^^^
  File "/Users/krohn/PycharmProjects/DME-AGENTS/dgi-extractor/.venv/lib/python3.12/site-packages/django/db/backends/base/base.py", line 278, in ensure_connection
    with self.wrap_database_errors:
         ^^^^^^^^^^^^^^^^^^^^^^^^^
  File "/Users/krohn/PycharmProjects/DME-AGENTS/dgi-extractor/.venv/lib/python3.12/site-packages/django/db/utils.py", line 91, in __exit__
    raise dj_exc_value.with_traceback(traceback) from exc_value
  File "/Users/krohn/PycharmProjects/DME-AGENTS/dgi-extractor/.venv/lib/python3.12/site-packages/django/db/backends/base/base.py", line 279, in ensure_connection
    self.connect()
  File "/Users/krohn/PycharmProjects/DME-AGENTS/dgi-extractor/.venv/lib/python3.12/site-packages/django/utils/asyncio.py", line 26, in inner
    return func(*args, **kwargs)
           ^^^^^^^^^^^^^^^^^^^^^
  File "/Users/krohn/PycharmProjects/DME-AGENTS/dgi-extractor/.venv/lib/python3.12/site-packages/django/db/backends/base/base.py", line 256, in connect
    self.connection = self.get_new_connection(conn_params)
                      ^^^^^^^^^^^^^^^^^^^^^^^^^^^^^^^^^^^^
  File "/Users/krohn/PycharmProjects/DME-AGENTS/dgi-extractor/.venv/lib/python3.12/site-packages/django/utils/asyncio.py", line 26, in inner
    return func(*args, **kwargs)
           ^^^^^^^^^^^^^^^^^^^^^
  File "/Users/krohn/PycharmProjects/DME-AGENTS/dgi-extractor/.venv/lib/python3.12/site-packages/django/db/backends/postgresql/base.py", line 332, in get_new_connection
    connection = self.Database.connect(**conn_params)
                 ^^^^^^^^^^^^^^^^^^^^^^^^^^^^^^^^^^^^
  File "/Users/krohn/PycharmProjects/DME-AGENTS/dgi-extractor/.venv/lib/python3.12/site-packages/psycopg2/__init__.py", line 122, in connect
    conn = _connect(dsn, connection_factory=connection_factory, **kwasync)
           ^^^^^^^^^^^^^^^^^^^^^^^^^^^^^^^^^^^^^^^^^^^^^^^^^^^^^^^^^^^^^^^
django.db.utils.OperationalError: connection to server at "37.60.239.221", port 5433 failed: Network is unreachable
	Is the server running on that host and accepting TCP/IP connections?

ERROR 2025-10-07 11:54:37,706 basehttp 42024 123145362857984 "POST /api/v1/processing/rag/query/ HTTP/1.1" 500 153060
ERROR 2025-10-07 11:54:53,461 log 42024 123145362857984 Internal Server Error: /api/v1/processing/rag/query/
Traceback (most recent call last):
  File "/Users/krohn/PycharmProjects/DME-AGENTS/dgi-extractor/.venv/lib/python3.12/site-packages/django/db/backends/base/base.py", line 279, in ensure_connection
    self.connect()
  File "/Users/krohn/PycharmProjects/DME-AGENTS/dgi-extractor/.venv/lib/python3.12/site-packages/django/utils/asyncio.py", line 26, in inner
    return func(*args, **kwargs)
           ^^^^^^^^^^^^^^^^^^^^^
  File "/Users/krohn/PycharmProjects/DME-AGENTS/dgi-extractor/.venv/lib/python3.12/site-packages/django/db/backends/base/base.py", line 256, in connect
    self.connection = self.get_new_connection(conn_params)
                      ^^^^^^^^^^^^^^^^^^^^^^^^^^^^^^^^^^^^
  File "/Users/krohn/PycharmProjects/DME-AGENTS/dgi-extractor/.venv/lib/python3.12/site-packages/django/utils/asyncio.py", line 26, in inner
    return func(*args, **kwargs)
           ^^^^^^^^^^^^^^^^^^^^^
  File "/Users/krohn/PycharmProjects/DME-AGENTS/dgi-extractor/.venv/lib/python3.12/site-packages/django/db/backends/postgresql/base.py", line 332, in get_new_connection
    connection = self.Database.connect(**conn_params)
                 ^^^^^^^^^^^^^^^^^^^^^^^^^^^^^^^^^^^^
  File "/Users/krohn/PycharmProjects/DME-AGENTS/dgi-extractor/.venv/lib/python3.12/site-packages/psycopg2/__init__.py", line 122, in connect
    conn = _connect(dsn, connection_factory=connection_factory, **kwasync)
           ^^^^^^^^^^^^^^^^^^^^^^^^^^^^^^^^^^^^^^^^^^^^^^^^^^^^^^^^^^^^^^^
psycopg2.OperationalError: connection to server at "37.60.239.221", port 5433 failed: Network is unreachable
	Is the server running on that host and accepting TCP/IP connections?


The above exception was the direct cause of the following exception:

Traceback (most recent call last):
  File "/Users/krohn/PycharmProjects/DME-AGENTS/dgi-extractor/.venv/lib/python3.12/site-packages/django/core/handlers/exception.py", line 55, in inner
    response = get_response(request)
               ^^^^^^^^^^^^^^^^^^^^^
  File "/Users/krohn/PycharmProjects/DME-AGENTS/dgi-extractor/.venv/lib/python3.12/site-packages/django/core/handlers/base.py", line 197, in _get_response
    response = wrapped_callback(request, *callback_args, **callback_kwargs)
               ^^^^^^^^^^^^^^^^^^^^^^^^^^^^^^^^^^^^^^^^^^^^^^^^^^^^^^^^^^^^
  File "/Library/Frameworks/Python.framework/Versions/3.12/lib/python3.12/contextlib.py", line 80, in inner
    with self._recreate_cm():
         ^^^^^^^^^^^^^^^^^^^
  File "/Users/krohn/PycharmProjects/DME-AGENTS/dgi-extractor/.venv/lib/python3.12/site-packages/django/db/transaction.py", line 198, in __enter__
    if not connection.get_autocommit():
           ^^^^^^^^^^^^^^^^^^^^^^^^^^^
  File "/Users/krohn/PycharmProjects/DME-AGENTS/dgi-extractor/.venv/lib/python3.12/site-packages/django/db/backends/base/base.py", line 454, in get_autocommit
    self.ensure_connection()
  File "/Users/krohn/PycharmProjects/DME-AGENTS/dgi-extractor/.venv/lib/python3.12/site-packages/django/utils/asyncio.py", line 26, in inner
    return func(*args, **kwargs)
           ^^^^^^^^^^^^^^^^^^^^^
  File "/Users/krohn/PycharmProjects/DME-AGENTS/dgi-extractor/.venv/lib/python3.12/site-packages/django/db/backends/base/base.py", line 278, in ensure_connection
    with self.wrap_database_errors:
         ^^^^^^^^^^^^^^^^^^^^^^^^^
  File "/Users/krohn/PycharmProjects/DME-AGENTS/dgi-extractor/.venv/lib/python3.12/site-packages/django/db/utils.py", line 91, in __exit__
    raise dj_exc_value.with_traceback(traceback) from exc_value
  File "/Users/krohn/PycharmProjects/DME-AGENTS/dgi-extractor/.venv/lib/python3.12/site-packages/django/db/backends/base/base.py", line 279, in ensure_connection
    self.connect()
  File "/Users/krohn/PycharmProjects/DME-AGENTS/dgi-extractor/.venv/lib/python3.12/site-packages/django/utils/asyncio.py", line 26, in inner
    return func(*args, **kwargs)
           ^^^^^^^^^^^^^^^^^^^^^
  File "/Users/krohn/PycharmProjects/DME-AGENTS/dgi-extractor/.venv/lib/python3.12/site-packages/django/db/backends/base/base.py", line 256, in connect
    self.connection = self.get_new_connection(conn_params)
                      ^^^^^^^^^^^^^^^^^^^^^^^^^^^^^^^^^^^^
  File "/Users/krohn/PycharmProjects/DME-AGENTS/dgi-extractor/.venv/lib/python3.12/site-packages/django/utils/asyncio.py", line 26, in inner
    return func(*args, **kwargs)
           ^^^^^^^^^^^^^^^^^^^^^
  File "/Users/krohn/PycharmProjects/DME-AGENTS/dgi-extractor/.venv/lib/python3.12/site-packages/django/db/backends/postgresql/base.py", line 332, in get_new_connection
    connection = self.Database.connect(**conn_params)
                 ^^^^^^^^^^^^^^^^^^^^^^^^^^^^^^^^^^^^
  File "/Users/krohn/PycharmProjects/DME-AGENTS/dgi-extractor/.venv/lib/python3.12/site-packages/psycopg2/__init__.py", line 122, in connect
    conn = _connect(dsn, connection_factory=connection_factory, **kwasync)
           ^^^^^^^^^^^^^^^^^^^^^^^^^^^^^^^^^^^^^^^^^^^^^^^^^^^^^^^^^^^^^^^
django.db.utils.OperationalError: connection to server at "37.60.239.221", port 5433 failed: Network is unreachable
	Is the server running on that host and accepting TCP/IP connections?

ERROR 2025-10-07 11:54:53,484 basehttp 42024 123145362857984 "POST /api/v1/processing/rag/query/ HTTP/1.1" 500 153060
ERROR 2025-10-07 12:31:07,683 log 42024 123145363394560 Internal Server Error: /api/v1/processing/rag/query/
Traceback (most recent call last):
  File "/Users/krohn/PycharmProjects/DME-AGENTS/dgi-extractor/.venv/lib/python3.12/site-packages/django/db/backends/base/base.py", line 279, in ensure_connection
    self.connect()
  File "/Users/krohn/PycharmProjects/DME-AGENTS/dgi-extractor/.venv/lib/python3.12/site-packages/django/utils/asyncio.py", line 26, in inner
    return func(*args, **kwargs)
           ^^^^^^^^^^^^^^^^^^^^^
  File "/Users/krohn/PycharmProjects/DME-AGENTS/dgi-extractor/.venv/lib/python3.12/site-packages/django/db/backends/base/base.py", line 256, in connect
    self.connection = self.get_new_connection(conn_params)
                      ^^^^^^^^^^^^^^^^^^^^^^^^^^^^^^^^^^^^
  File "/Users/krohn/PycharmProjects/DME-AGENTS/dgi-extractor/.venv/lib/python3.12/site-packages/django/utils/asyncio.py", line 26, in inner
    return func(*args, **kwargs)
           ^^^^^^^^^^^^^^^^^^^^^
  File "/Users/krohn/PycharmProjects/DME-AGENTS/dgi-extractor/.venv/lib/python3.12/site-packages/django/db/backends/postgresql/base.py", line 332, in get_new_connection
    connection = self.Database.connect(**conn_params)
                 ^^^^^^^^^^^^^^^^^^^^^^^^^^^^^^^^^^^^
  File "/Users/krohn/PycharmProjects/DME-AGENTS/dgi-extractor/.venv/lib/python3.12/site-packages/psycopg2/__init__.py", line 122, in connect
    conn = _connect(dsn, connection_factory=connection_factory, **kwasync)
           ^^^^^^^^^^^^^^^^^^^^^^^^^^^^^^^^^^^^^^^^^^^^^^^^^^^^^^^^^^^^^^^
psycopg2.OperationalError: connection to server at "37.60.239.221", port 5433 failed: Network is unreachable
	Is the server running on that host and accepting TCP/IP connections?


The above exception was the direct cause of the following exception:

Traceback (most recent call last):
  File "/Users/krohn/PycharmProjects/DME-AGENTS/dgi-extractor/.venv/lib/python3.12/site-packages/django/core/handlers/exception.py", line 55, in inner
    response = get_response(request)
               ^^^^^^^^^^^^^^^^^^^^^
  File "/Users/krohn/PycharmProjects/DME-AGENTS/dgi-extractor/.venv/lib/python3.12/site-packages/django/core/handlers/base.py", line 197, in _get_response
    response = wrapped_callback(request, *callback_args, **callback_kwargs)
               ^^^^^^^^^^^^^^^^^^^^^^^^^^^^^^^^^^^^^^^^^^^^^^^^^^^^^^^^^^^^
  File "/Library/Frameworks/Python.framework/Versions/3.12/lib/python3.12/contextlib.py", line 80, in inner
    with self._recreate_cm():
         ^^^^^^^^^^^^^^^^^^^
  File "/Users/krohn/PycharmProjects/DME-AGENTS/dgi-extractor/.venv/lib/python3.12/site-packages/django/db/transaction.py", line 198, in __enter__
    if not connection.get_autocommit():
           ^^^^^^^^^^^^^^^^^^^^^^^^^^^
  File "/Users/krohn/PycharmProjects/DME-AGENTS/dgi-extractor/.venv/lib/python3.12/site-packages/django/db/backends/base/base.py", line 454, in get_autocommit
    self.ensure_connection()
  File "/Users/krohn/PycharmProjects/DME-AGENTS/dgi-extractor/.venv/lib/python3.12/site-packages/django/utils/asyncio.py", line 26, in inner
    return func(*args, **kwargs)
           ^^^^^^^^^^^^^^^^^^^^^
  File "/Users/krohn/PycharmProjects/DME-AGENTS/dgi-extractor/.venv/lib/python3.12/site-packages/django/db/backends/base/base.py", line 278, in ensure_connection
    with self.wrap_database_errors:
         ^^^^^^^^^^^^^^^^^^^^^^^^^
  File "/Users/krohn/PycharmProjects/DME-AGENTS/dgi-extractor/.venv/lib/python3.12/site-packages/django/db/utils.py", line 91, in __exit__
    raise dj_exc_value.with_traceback(traceback) from exc_value
  File "/Users/krohn/PycharmProjects/DME-AGENTS/dgi-extractor/.venv/lib/python3.12/site-packages/django/db/backends/base/base.py", line 279, in ensure_connection
    self.connect()
  File "/Users/krohn/PycharmProjects/DME-AGENTS/dgi-extractor/.venv/lib/python3.12/site-packages/django/utils/asyncio.py", line 26, in inner
    return func(*args, **kwargs)
           ^^^^^^^^^^^^^^^^^^^^^
  File "/Users/krohn/PycharmProjects/DME-AGENTS/dgi-extractor/.venv/lib/python3.12/site-packages/django/db/backends/base/base.py", line 256, in connect
    self.connection = self.get_new_connection(conn_params)
                      ^^^^^^^^^^^^^^^^^^^^^^^^^^^^^^^^^^^^
  File "/Users/krohn/PycharmProjects/DME-AGENTS/dgi-extractor/.venv/lib/python3.12/site-packages/django/utils/asyncio.py", line 26, in inner
    return func(*args, **kwargs)
           ^^^^^^^^^^^^^^^^^^^^^
  File "/Users/krohn/PycharmProjects/DME-AGENTS/dgi-extractor/.venv/lib/python3.12/site-packages/django/db/backends/postgresql/base.py", line 332, in get_new_connection
    connection = self.Database.connect(**conn_params)
                 ^^^^^^^^^^^^^^^^^^^^^^^^^^^^^^^^^^^^
  File "/Users/krohn/PycharmProjects/DME-AGENTS/dgi-extractor/.venv/lib/python3.12/site-packages/psycopg2/__init__.py", line 122, in connect
    conn = _connect(dsn, connection_factory=connection_factory, **kwasync)
           ^^^^^^^^^^^^^^^^^^^^^^^^^^^^^^^^^^^^^^^^^^^^^^^^^^^^^^^^^^^^^^^
django.db.utils.OperationalError: connection to server at "37.60.239.221", port 5433 failed: Network is unreachable
	Is the server running on that host and accepting TCP/IP connections?

ERROR 2025-10-07 12:31:09,254 basehttp 42024 123145363394560 "POST /api/v1/processing/rag/query/ HTTP/1.1" 500 153060
ERROR 2025-10-07 13:34:20,478 log 42024 123145363394560 Internal Server Error: /api/v1/processing/rag/query/
Traceback (most recent call last):
  File "/Users/krohn/PycharmProjects/DME-AGENTS/dgi-extractor/.venv/lib/python3.12/site-packages/django/db/backends/base/base.py", line 279, in ensure_connection
    self.connect()
  File "/Users/krohn/PycharmProjects/DME-AGENTS/dgi-extractor/.venv/lib/python3.12/site-packages/django/utils/asyncio.py", line 26, in inner
    return func(*args, **kwargs)
           ^^^^^^^^^^^^^^^^^^^^^
  File "/Users/krohn/PycharmProjects/DME-AGENTS/dgi-extractor/.venv/lib/python3.12/site-packages/django/db/backends/base/base.py", line 256, in connect
    self.connection = self.get_new_connection(conn_params)
                      ^^^^^^^^^^^^^^^^^^^^^^^^^^^^^^^^^^^^
  File "/Users/krohn/PycharmProjects/DME-AGENTS/dgi-extractor/.venv/lib/python3.12/site-packages/django/utils/asyncio.py", line 26, in inner
    return func(*args, **kwargs)
           ^^^^^^^^^^^^^^^^^^^^^
  File "/Users/krohn/PycharmProjects/DME-AGENTS/dgi-extractor/.venv/lib/python3.12/site-packages/django/db/backends/postgresql/base.py", line 332, in get_new_connection
    connection = self.Database.connect(**conn_params)
                 ^^^^^^^^^^^^^^^^^^^^^^^^^^^^^^^^^^^^
  File "/Users/krohn/PycharmProjects/DME-AGENTS/dgi-extractor/.venv/lib/python3.12/site-packages/psycopg2/__init__.py", line 122, in connect
    conn = _connect(dsn, connection_factory=connection_factory, **kwasync)
           ^^^^^^^^^^^^^^^^^^^^^^^^^^^^^^^^^^^^^^^^^^^^^^^^^^^^^^^^^^^^^^^
psycopg2.OperationalError: connection to server at "37.60.239.221", port 5433 failed: Network is unreachable
	Is the server running on that host and accepting TCP/IP connections?


The above exception was the direct cause of the following exception:

Traceback (most recent call last):
  File "/Users/krohn/PycharmProjects/DME-AGENTS/dgi-extractor/.venv/lib/python3.12/site-packages/django/core/handlers/exception.py", line 55, in inner
    response = get_response(request)
               ^^^^^^^^^^^^^^^^^^^^^
  File "/Users/krohn/PycharmProjects/DME-AGENTS/dgi-extractor/.venv/lib/python3.12/site-packages/django/core/handlers/base.py", line 197, in _get_response
    response = wrapped_callback(request, *callback_args, **callback_kwargs)
               ^^^^^^^^^^^^^^^^^^^^^^^^^^^^^^^^^^^^^^^^^^^^^^^^^^^^^^^^^^^^
  File "/Library/Frameworks/Python.framework/Versions/3.12/lib/python3.12/contextlib.py", line 80, in inner
    with self._recreate_cm():
         ^^^^^^^^^^^^^^^^^^^
  File "/Users/krohn/PycharmProjects/DME-AGENTS/dgi-extractor/.venv/lib/python3.12/site-packages/django/db/transaction.py", line 198, in __enter__
    if not connection.get_autocommit():
           ^^^^^^^^^^^^^^^^^^^^^^^^^^^
  File "/Users/krohn/PycharmProjects/DME-AGENTS/dgi-extractor/.venv/lib/python3.12/site-packages/django/db/backends/base/base.py", line 454, in get_autocommit
    self.ensure_connection()
  File "/Users/krohn/PycharmProjects/DME-AGENTS/dgi-extractor/.venv/lib/python3.12/site-packages/django/utils/asyncio.py", line 26, in inner
    return func(*args, **kwargs)
           ^^^^^^^^^^^^^^^^^^^^^
  File "/Users/krohn/PycharmProjects/DME-AGENTS/dgi-extractor/.venv/lib/python3.12/site-packages/django/db/backends/base/base.py", line 278, in ensure_connection
    with self.wrap_database_errors:
         ^^^^^^^^^^^^^^^^^^^^^^^^^
  File "/Users/krohn/PycharmProjects/DME-AGENTS/dgi-extractor/.venv/lib/python3.12/site-packages/django/db/utils.py", line 91, in __exit__
    raise dj_exc_value.with_traceback(traceback) from exc_value
  File "/Users/krohn/PycharmProjects/DME-AGENTS/dgi-extractor/.venv/lib/python3.12/site-packages/django/db/backends/base/base.py", line 279, in ensure_connection
    self.connect()
  File "/Users/krohn/PycharmProjects/DME-AGENTS/dgi-extractor/.venv/lib/python3.12/site-packages/django/utils/asyncio.py", line 26, in inner
    return func(*args, **kwargs)
           ^^^^^^^^^^^^^^^^^^^^^
  File "/Users/krohn/PycharmProjects/DME-AGENTS/dgi-extractor/.venv/lib/python3.12/site-packages/django/db/backends/base/base.py", line 256, in connect
    self.connection = self.get_new_connection(conn_params)
                      ^^^^^^^^^^^^^^^^^^^^^^^^^^^^^^^^^^^^
  File "/Users/krohn/PycharmProjects/DME-AGENTS/dgi-extractor/.venv/lib/python3.12/site-packages/django/utils/asyncio.py", line 26, in inner
    return func(*args, **kwargs)
           ^^^^^^^^^^^^^^^^^^^^^
  File "/Users/krohn/PycharmProjects/DME-AGENTS/dgi-extractor/.venv/lib/python3.12/site-packages/django/db/backends/postgresql/base.py", line 332, in get_new_connection
    connection = self.Database.connect(**conn_params)
                 ^^^^^^^^^^^^^^^^^^^^^^^^^^^^^^^^^^^^
  File "/Users/krohn/PycharmProjects/DME-AGENTS/dgi-extractor/.venv/lib/python3.12/site-packages/psycopg2/__init__.py", line 122, in connect
    conn = _connect(dsn, connection_factory=connection_factory, **kwasync)
           ^^^^^^^^^^^^^^^^^^^^^^^^^^^^^^^^^^^^^^^^^^^^^^^^^^^^^^^^^^^^^^^
django.db.utils.OperationalError: connection to server at "37.60.239.221", port 5433 failed: Network is unreachable
	Is the server running on that host and accepting TCP/IP connections?

ERROR 2025-10-07 13:34:26,539 basehttp 42024 123145363394560 "POST /api/v1/processing/rag/query/ HTTP/1.1" 500 153060
ERROR 2025-10-07 13:34:48,332 log 42024 123145380184064 Internal Server Error: /api/v1/processing/rag/query/
Traceback (most recent call last):
  File "/Users/krohn/PycharmProjects/DME-AGENTS/dgi-extractor/.venv/lib/python3.12/site-packages/django/db/backends/base/base.py", line 279, in ensure_connection
    self.connect()
  File "/Users/krohn/PycharmProjects/DME-AGENTS/dgi-extractor/.venv/lib/python3.12/site-packages/django/utils/asyncio.py", line 26, in inner
    return func(*args, **kwargs)
           ^^^^^^^^^^^^^^^^^^^^^
  File "/Users/krohn/PycharmProjects/DME-AGENTS/dgi-extractor/.venv/lib/python3.12/site-packages/django/db/backends/base/base.py", line 256, in connect
    self.connection = self.get_new_connection(conn_params)
                      ^^^^^^^^^^^^^^^^^^^^^^^^^^^^^^^^^^^^
  File "/Users/krohn/PycharmProjects/DME-AGENTS/dgi-extractor/.venv/lib/python3.12/site-packages/django/utils/asyncio.py", line 26, in inner
    return func(*args, **kwargs)
           ^^^^^^^^^^^^^^^^^^^^^
  File "/Users/krohn/PycharmProjects/DME-AGENTS/dgi-extractor/.venv/lib/python3.12/site-packages/django/db/backends/postgresql/base.py", line 332, in get_new_connection
    connection = self.Database.connect(**conn_params)
                 ^^^^^^^^^^^^^^^^^^^^^^^^^^^^^^^^^^^^
  File "/Users/krohn/PycharmProjects/DME-AGENTS/dgi-extractor/.venv/lib/python3.12/site-packages/psycopg2/__init__.py", line 122, in connect
    conn = _connect(dsn, connection_factory=connection_factory, **kwasync)
           ^^^^^^^^^^^^^^^^^^^^^^^^^^^^^^^^^^^^^^^^^^^^^^^^^^^^^^^^^^^^^^^
psycopg2.OperationalError: connection to server at "37.60.239.221", port 5433 failed: Network is unreachable
	Is the server running on that host and accepting TCP/IP connections?


The above exception was the direct cause of the following exception:

Traceback (most recent call last):
  File "/Users/krohn/PycharmProjects/DME-AGENTS/dgi-extractor/.venv/lib/python3.12/site-packages/django/core/handlers/exception.py", line 55, in inner
    response = get_response(request)
               ^^^^^^^^^^^^^^^^^^^^^
  File "/Users/krohn/PycharmProjects/DME-AGENTS/dgi-extractor/.venv/lib/python3.12/site-packages/django/core/handlers/base.py", line 197, in _get_response
    response = wrapped_callback(request, *callback_args, **callback_kwargs)
               ^^^^^^^^^^^^^^^^^^^^^^^^^^^^^^^^^^^^^^^^^^^^^^^^^^^^^^^^^^^^
  File "/Library/Frameworks/Python.framework/Versions/3.12/lib/python3.12/contextlib.py", line 80, in inner
    with self._recreate_cm():
         ^^^^^^^^^^^^^^^^^^^
  File "/Users/krohn/PycharmProjects/DME-AGENTS/dgi-extractor/.venv/lib/python3.12/site-packages/django/db/transaction.py", line 198, in __enter__
    if not connection.get_autocommit():
           ^^^^^^^^^^^^^^^^^^^^^^^^^^^
  File "/Users/krohn/PycharmProjects/DME-AGENTS/dgi-extractor/.venv/lib/python3.12/site-packages/django/db/backends/base/base.py", line 454, in get_autocommit
    self.ensure_connection()
  File "/Users/krohn/PycharmProjects/DME-AGENTS/dgi-extractor/.venv/lib/python3.12/site-packages/django/utils/asyncio.py", line 26, in inner
    return func(*args, **kwargs)
           ^^^^^^^^^^^^^^^^^^^^^
  File "/Users/krohn/PycharmProjects/DME-AGENTS/dgi-extractor/.venv/lib/python3.12/site-packages/django/db/backends/base/base.py", line 278, in ensure_connection
    with self.wrap_database_errors:
         ^^^^^^^^^^^^^^^^^^^^^^^^^
  File "/Users/krohn/PycharmProjects/DME-AGENTS/dgi-extractor/.venv/lib/python3.12/site-packages/django/db/utils.py", line 91, in __exit__
    raise dj_exc_value.with_traceback(traceback) from exc_value
  File "/Users/krohn/PycharmProjects/DME-AGENTS/dgi-extractor/.venv/lib/python3.12/site-packages/django/db/backends/base/base.py", line 279, in ensure_connection
    self.connect()
  File "/Users/krohn/PycharmProjects/DME-AGENTS/dgi-extractor/.venv/lib/python3.12/site-packages/django/utils/asyncio.py", line 26, in inner
    return func(*args, **kwargs)
           ^^^^^^^^^^^^^^^^^^^^^
  File "/Users/krohn/PycharmProjects/DME-AGENTS/dgi-extractor/.venv/lib/python3.12/site-packages/django/db/backends/base/base.py", line 256, in connect
    self.connection = self.get_new_connection(conn_params)
                      ^^^^^^^^^^^^^^^^^^^^^^^^^^^^^^^^^^^^
  File "/Users/krohn/PycharmProjects/DME-AGENTS/dgi-extractor/.venv/lib/python3.12/site-packages/django/utils/asyncio.py", line 26, in inner
    return func(*args, **kwargs)
           ^^^^^^^^^^^^^^^^^^^^^
  File "/Users/krohn/PycharmProjects/DME-AGENTS/dgi-extractor/.venv/lib/python3.12/site-packages/django/db/backends/postgresql/base.py", line 332, in get_new_connection
    connection = self.Database.connect(**conn_params)
                 ^^^^^^^^^^^^^^^^^^^^^^^^^^^^^^^^^^^^
  File "/Users/krohn/PycharmProjects/DME-AGENTS/dgi-extractor/.venv/lib/python3.12/site-packages/psycopg2/__init__.py", line 122, in connect
    conn = _connect(dsn, connection_factory=connection_factory, **kwasync)
           ^^^^^^^^^^^^^^^^^^^^^^^^^^^^^^^^^^^^^^^^^^^^^^^^^^^^^^^^^^^^^^^
django.db.utils.OperationalError: connection to server at "37.60.239.221", port 5433 failed: Network is unreachable
	Is the server running on that host and accepting TCP/IP connections?

ERROR 2025-10-07 13:34:48,338 basehttp 42024 123145380184064 "POST /api/v1/processing/rag/query/ HTTP/1.1" 500 151280
INFO 2025-10-07 13:35:06,407 autoreload 51195 140704670657024 Watching for file changes with StatReloader
WARNING 2025-10-07 13:36:08,412 log 51195 123145507454976 Bad Request: /api/v1/processing/rag/query/
WARNING 2025-10-07 13:36:08,412 basehttp 51195 123145507454976 "POST /api/v1/processing/rag/query/ HTTP/1.1" 400 44
WARNING 2025-10-07 13:37:03,626 log 51195 123145507454976 Bad Request: /api/v1/processing/rag/query/
WARNING 2025-10-07 13:37:03,627 basehttp 51195 123145507454976 "POST /api/v1/processing/rag/query/ HTTP/1.1" 400 44
INFO 2025-10-07 13:38:30,137 basehttp 51195 123145524244480 "POST /api/v1/processing/rag/query/ HTTP/1.1" 200 4234
INFO 2025-10-07 13:42:26,070 basehttp 51195 123145507454976 "GET /api/v1/public/all-extracted-content/?page=1&page_size=10 HTTP/1.1" 200 20790
INFO 2025-10-07 13:42:46,314 basehttp 51195 123145524244480 "POST /api/v1/processing/rag/query/ HTTP/1.1" 200 4365
INFO 2025-10-07 13:42:46,314 basehttp 51195 123145524244480 - Broken pipe from ('127.0.0.1', 58951)
INFO 2025-10-07 13:43:37,870 basehttp 51195 123145507454976 "POST /api/v1/processing/rag/query/ HTTP/1.1" 200 4484
INFO 2025-10-07 13:43:37,871 basehttp 51195 123145507454976 - Broken pipe from ('127.0.0.1', 57507)
INFO 2025-10-07 13:45:32,852 basehttp 51195 123145507454976 "GET /api/v1/public/all-extracted-content/?page=1&page_size=10 HTTP/1.1" 200 20789
INFO 2025-10-07 13:46:38,807 basehttp 51195 123145507454976 "POST /api/v1/processing/rag/query/ HTTP/1.1" 200 411
INFO 2025-10-07 13:48:26,951 basehttp 51195 123145507454976 "POST /api/v1/processing/rag/query/ HTTP/1.1" 200 4151
INFO 2025-10-07 13:50:29,935 basehttp 51195 123145507454976 "POST /api/v1/processing/rag/query/ HTTP/1.1" 200 4196
INFO 2025-10-07 13:59:34,350 basehttp 51195 123145524244480 "POST /api/v1/processing/rag/query/ HTTP/1.1" 200 4260
INFO 2025-10-07 14:01:05,838 basehttp 51195 123145507454976 "POST /api/v1/processing/rag/query/ HTTP/1.1" 200 4096
INFO 2025-10-07 14:26:00,169 basehttp 51195 123145507454976 "OPTIONS /api/v1/public/documents/1212a9a9-dcca-4733-8f81-2b67dd406626/structure/ HTTP/1.1" 200 0
